Workbook

Sheet 3wh sale 
H2: Days | I2: 10
C3: 3WH Daily Sale Monitoring
B4: Type | C4: Line | D4: 46143 | E4: Daily Plan | F4: Avg Par Day Sales Qty | G4: Total Sale Qty | H4: Bal Excess Short | I4: Daily Ach % | J4: Month Ach % | K4: =+L4+1 -> 46155 | L4: =+M4+1 -> 46154 | M4: =+N4+1 -> 46153 | N4: =+O4+1 -> 46152 | O4: =+P4+1 -> 46151 | P4: =+Q4+1 -> 46150 | Q4: =+R4+1 -> 46149 | R4: =+S4+1 -> 46148 | ... V4: =+W4+1 -> 46144 | W4: 46143
B5: Re Body Part | C5: RE STYLING | D5: =+Monthly!AD35 -> 24224.68 | E5: =+D5/26 -> 931.71846 | F5: =+G5/$I$2 -> 820.5 | G5: =SUM(K5:W5) -> 8205 | H5: FG body | I5: =+F5/E5 -> 0.88063083 | J5: =+G5/D5 -> 0.33870416 | K5: =VLOOKUP(C5,Sheet8!$A$5:$N$21,14,0) -> 807 | L5: =VLOOKUP(C5,Sheet8!$A$5:$M$21,13,0) -> 633 | M5: =VLOOKUP(C5,Sheet8!$A$5:$L$22,12,0) -> 759 | N5: =VLOOKUP(C5,Sheet8!$A$5:$K$20,11,0) -> 120 | O5: =VLOOKUP(C5,Sheet8!$A$5:$J$20,10,0) -> 846 | P5: =VLOOKUP(C5,Sheet8!$A$5:$I$20,9,0) -> 861 | Q5: =VLOOKUP(C5,Sheet8!$A$5:$H$20,8,0) -> 705 | R5: =VLOOKUP(C5,Sheet8!$A$5:$G$21,7,0) -> 822 | S5: =VLOOKUP(C5,Sheet8!$A$5:$F$20,6,0) -> 885 | T5: =VLOOKUP(C5,Sheet8!$A$5:$E$20,5,0) -> 516 | U5: =VLOOKUP(C5,Sheet8!$A$5:$D$20,4,0) -> 630 | V5: =VLOOKUP(C5,Sheet8!$A$5:$C$20,3,0) -> 501 | W5: =VLOOKUP(C5,Sheet8!$A$5:$B$20,2,0) -> 120
C6: FRONT MUDGAURD | D6: =+Monthly!AD47+Monthly!AD48 -> 63224 | E6: =+D6/26 -> 2431.6923 | F6: =+G6/$I$2 -> 2056.3 | G6: =SUM(K6:W6) -> 20563 | H6: =+G6-(G5*2+G12+G14) -> 1369 | I6: =+F6/E6 -> 0.84562508 | J6: =+G6/D6 -> 0.32524042 | K6: =VLOOKUP(C6,Sheet8!$A$5:$N$21,14,0) -> 2204 | L6: =VLOOKUP(C6,Sheet8!$A$5:$M$21,13,0) -> 2120 | M6: =VLOOKUP(C6,Sheet8!$A$5:$L$22,12,0) -> 2410 | N6: =VLOOKUP(C6,Sheet8!$A$5:$K$20,11,0) -> 0 | O6: =VLOOKUP(C6,Sheet8!$A$5:$J$20,10,0) -> 2080 | P6: =VLOOKUP(C6,Sheet8!$A$5:$I$20,9,0) -> 2350 | Q6: =VLOOKUP(C6,Sheet8!$A$5:$H$20,8,0) -> 1280 | R6: =VLOOKUP(C6,Sheet8!$A$5:$G$21,7,0) -> 2139 | S6: =VLOOKUP(C6,Sheet8!$A$5:$F$20,6,0) -> 2080 | T6: =VLOOKUP(C6,Sheet8!$A$5:$E$20,5,0) -> 1660 | U6: =VLOOKUP(C6,Sheet8!$A$5:$D$20,4,0) -> 1280 | V6: =VLOOKUP(C6,Sheet8!$A$5:$C$20,3,0) -> 960 | W6: =VLOOKUP(C6,Sheet8!$A$5:$B$20,2,0) -> 0
C7: FRONT MUDGAURD EV | D7: =+Monthly!AD49 -> 2596 | E7: =+D7/26 -> 99.846154 | F7: =+G7/$I$2 -> 35 | G7: =SUM(K7:W7) -> 350 | H7: =+(G7-E7*I2) -> -648.46154 | I7: =+F7/E7 -> 0.35053929 | J7: =+G7/D7 -> 0.1348228 | K7: =VLOOKUP(C7,Sheet8!$A$5:$N$21,14,0) -> 100 | L7: =VLOOKUP(C7,Sheet8!$A$5:$M$21,13,0) -> 100 | M7: =VLOOKUP(C7,Sheet8!$A$5:$L$22,12,0) -> 150 | N7: 0 | O7: 0 | P7: 0 | Q7: 0 | R7: 0 | S7: 0 | T7: 0 | U7: 0 | V7: 0 | W7: 0
C8: REAR MUDGAURD | D8: =+Monthly!AD46 -> 97110 | E8: =+D8/26 -> 3735 | F8: =+G8/$I$2 -> 4924.8 | G8: =SUM(K8:W8) -> 49248 | H8: =+(G8-G5*4) -> 16428 | I8: =+F8/E8 -> 1.3185542 | J8: =+G8/D8 -> 0.50713624 | K8: =VLOOKUP(C8,Sheet8!$A$5:$N$21,14,0) -> 3456 | L8: =VLOOKUP(C8,Sheet8!$A$5:$M$21,13,0) -> 3888 | M8: =VLOOKUP(C8,Sheet8!$A$5:$L$22,12,0) -> 4320 | N8: =VLOOKUP(C8,Sheet8!$A$5:$K$20,11,0) -> 2160 | O8: =VLOOKUP(C8,Sheet8!$A$5:$J$20,10,0) -> 2592 | P8: =VLOOKUP(C8,Sheet8!$A$5:$I$20,9,0) -> 4320 | Q8: =VLOOKUP(C8,Sheet8!$A$5:$H$20,8,0) -> 4752 | R8: =VLOOKUP(C8,Sheet8!$A$5:$G$21,7,0) -> 3888 | S8: =VLOOKUP(C8,Sheet8!$A$5:$F$20,6,0) -> 5184 | T8: =VLOOKUP(C8,Sheet8!$A$5:$E$20,5,0) -> 4320 | U8: =VLOOKUP(C8,Sheet8!$A$5:$D$20,4,0) -> 5184 | V8: =VLOOKUP(C8,Sheet8!$A$5:$C$20,3,0) -> 5184 | W8: =VLOOKUP(C8,Sheet8!$A$5:$B$20,2,0) -> 0
C9: DASH BOARD | D9: =+Monthly!AD45 -> 77736 | E9: =+D9/26 -> 2989.8462 | F9: =+G9/$I$2 -> 2328 | G9: =SUM(K9:W9) -> 23280 | H9: =G9-(G5*2+G12+G14+G15) -> 868 | I9: =+F9/E9 -> 0.77863538 | J9: =+G9/D9 -> 0.29947515 | K9: =VLOOKUP(C9,Sheet8!$A$5:$N$21,14,0) -> 2082 | L9: =VLOOKUP(C9,Sheet8!$A$5:$M$21,13,0) -> 2118 | M9: =VLOOKUP(C9,Sheet8!$A$5:$L$22,12,0) -> 2038 | N9: =VLOOKUP(C9,Sheet8!$A$5:$K$20,11,0) -> 920 | O9: =VLOOKUP(C9,Sheet8!$A$5:$J$20,10,0) -> 1792 | P9: =VLOOKUP(C9,Sheet8!$A$5:$I$20,9,0) -> 2152 | Q9: =VLOOKUP(C9,Sheet8!$A$5:$H$20,8,0) -> 2448 | R9: =VLOOKUP(C9,Sheet8!$A$5:$G$21,7,0) -> 1224 | S9: =VLOOKUP(C9,Sheet8!$A$5:$F$20,6,0) -> 2428 | T9: =VLOOKUP(C9,Sheet8!$A$5:$E$20,5,0) -> 2362 | U9: =VLOOKUP(C9,Sheet8!$A$5:$D$20,4,0) -> 1240 | V9: =VLOOKUP(C9,Sheet8!$A$5:$C$20,3,0) -> 1660 | W9: =VLOOKUP(C9,Sheet8!$A$5:$B$20,2,0) -> 816
C10: STARTING HANDLE | D10: =+Monthly!AD61 -> 48629 | E10: =+D10/26 -> 1870.3462 | F10: =+G10/$I$2 -> 1402.9 | G10: =SUM(K10:W10) -> 14029 | H10: =+G10-G5*2 -> -2381 | I10: =+F10/E10 -> 0.75007506 | J10: =+G10/D10 -> 0.28849041 | K10: =VLOOKUP(C10,Sheet8!$A$5:$N$21,14,0) -> 1080 | L10: =VLOOKUP(C10,Sheet8!$A$5:$M$21,13,0) -> 1380 | M10: =VLOOKUP(C10,Sheet8!$A$5:$L$22,12,0) -> 1530 | N10: =VLOOKUP(C10,Sheet8!$A$5:$K$20,11,0) -> 0 | O10: =VLOOKUP(C10,Sheet8!$A$5:$J$20,10,0) -> 1079 | P10: =VLOOKUP(C10,Sheet8!$A$5:$I$20,9,0) -> 1080 | Q10: =VLOOKUP(C10,Sheet8!$A$5:$H$20,8,0) -> 1350 | R10: =VLOOKUP(C10,Sheet8!$A$5:$G$21,7,0) -> 1620 | S10: =VLOOKUP(C10,Sheet8!$A$5:$F$20,6,0) -> 1350 | T10: =VLOOKUP(C10,Sheet8!$A$5:$E$20,5,0) -> 1080 | U10: =VLOOKUP(C10,Sheet8!$A$5:$D$20,4,0) -> 720 | V10: =VLOOKUP(C10,Sheet8!$A$5:$C$20,3,0) -> 1760 | W10: =VLOOKUP(C10,Sheet8!$A$5:$B$20,2,0) -> 0
C11: SUPPORT TOP | D11: =+Monthly!AD64 -> 51825 | E11: =+D11/26 -> 1993.2692 | F11: =+G11/$I$2 -> 1698.1 | G11: =SUM(K11:W11) -> 16981 | H11: =+G11-G5*2 -> 571 | I11: =+F11/E11 -> 0.85191703 | J11: =+G11/D11 -> 0.3276604 | K11: =VLOOKUP(C11,Sheet8!$A$5:$N$21,14,0) -> 1473 | L11: =VLOOKUP(C11,Sheet8!$A$5:$M$21,13,0) -> 916 | M11: =VLOOKUP(C11,Sheet8!$A$5:$L$22,12,0) -> 1344 | N11: =VLOOKUP(C11,Sheet8!$A$5:$K$20,11,0) -> 0 | O11: =VLOOKUP(C11,Sheet8!$A$5:$J$20,10,0) -> 1200 | P11: =VLOOKUP(C11,Sheet8!$A$5:$I$20,9,0) -> 1688 | Q11: =VLOOKUP(C11,Sheet8!$A$5:$H$20,8,0) -> 1248 | R11: =VLOOKUP(C11,Sheet8!$A$5:$G$21,7,0) -> 1688 | S11: =VLOOKUP(C11,Sheet8!$A$5:$F$20,6,0) -> 2160 | T11: =VLOOKUP(C11,Sheet8!$A$5:$E$20,5,0) -> 1200 | U11: =VLOOKUP(C11,Sheet8!$A$5:$D$20,4,0) -> 1688 | V11: =VLOOKUP(C11,Sheet8!$A$5:$C$20,3,0) -> 2376 | W11: =VLOOKUP(C11,Sheet8!$A$5:$B$20,2,0) -> 0
B12: HD | C12: MAXIMA HD | D12: =+Monthly!AD41 -> 5819 | E12: =+D12/26 -> 223.80769 | F12: =+G12/$I$2 -> 141.8 | G12: =SUM(K12:W12) -> 1418 | H12: FG body | I12: =+F12/E12 -> 0.63357965 | J12: =+G12/D12 -> 0.24368448 | K12: =VLOOKUP(C12,Sheet8!$A$5:$N$21,14,0) -> 144 | L12: =VLOOKUP(C12,Sheet8!$A$5:$M$21,13,0) -> 152 | M12: =VLOOKUP(C12,Sheet8!$A$5:$L$22,12,0) -> 230 | N12: =VLOOKUP(C12,Sheet8!$A$5:$K$20,11,0) -> 0 | O12: =VLOOKUP(C12,Sheet8!$A$5:$J$20,10,0) -> 42 | P12: =VLOOKUP(C12,Sheet8!$A$5:$I$20,9,0) -> 124 | Q12: =VLOOKUP(C12,Sheet8!$A$5:$H$20,8,0) -> 158 | R12: =VLOOKUP(C12,Sheet8!$A$5:$G$21,7,0) -> 90 | S12: =VLOOKUP(C12,Sheet8!$A$5:$F$20,6,0) -> 144 | T12: =VLOOKUP(C12,Sheet8!$A$5:$E$20,5,0) -> 138 | U12: =VLOOKUP(C12,Sheet8!$A$5:$D$20,4,0) -> 24 | V12: =VLOOKUP(C12,Sheet8!$A$5:$C$20,3,0) -> 172 | W12: =VLOOKUP(C12,Sheet8!$A$5:$B$20,2,0) -> 0
C13: REAR COVER | D13: =+Monthly!AD67 -> 21876 | E13: =+D13/26 -> 841.38462 | F13: =+G13/$I$2 -> 338 | G13: =SUM(K13:W13) -> 3380 | H13: =+(G13-G12*2)/2 -> 272 | I13: 1 | J13: =+G13/D13 -> 0.15450722 | K13: =VLOOKUP(C13,Sheet8!$A$5:$N$21,14,0) -> 330 | L13: =VLOOKUP(C13,Sheet8!$A$5:$M$21,13,0) -> 440 | M13: =VLOOKUP(C13,Sheet8!$A$5:$L$22,12,0) -> 0 | N13: =VLOOKUP(C13,Sheet8!$A$5:$K$20,11,0) -> 0 | O13: =VLOOKUP(C13,Sheet8!$A$5:$J$20,10,0) -> 110 | P13: =VLOOKUP(C13,Sheet8!$A$5:$I$20,9,0) -> 330 | Q13: =VLOOKUP(C13,Sheet8!$A$5:$H$20,8,0) -> 330 | R13: =VLOOKUP(C13,Sheet8!$A$5:$G$21,7,0) -> 330 | S13: =VLOOKUP(C13,Sheet8!$A$5:$F$20,6,0) -> 440 | T13: =VLOOKUP(C13,Sheet8!$A$5:$E$20,5,0) -> 520 | U13: =VLOOKUP(C13,Sheet8!$A$5:$D$20,4,0) -> 330 | V13: =VLOOKUP(C13,Sheet8!$A$5:$C$20,3,0) -> 220 | W13: =VLOOKUP(C13,Sheet8!$A$5:$B$20,2,0) -> 0
B14: MAX UG | C14: MAX UG NEW | D14: =+Monthly!AD36 -> 4936 | E14: =+D14/26 -> 189.84615 | F14: =+G14/$I$2 -> 136.6 | G14: =SUM(K14:W14) -> 1366 | H14: =+(G14+G15)/(D14+D15) -> 0.32964188 | I14: =+F14/E14 -> 0.71952998 | J14: =+G14/D14 -> 0.2767423 | K14: =VLOOKUP(C14,Sheet8!$A$5:$N$21,14,0) -> 200 | L14: =VLOOKUP(C14,Sheet8!$A$5:$M$21,13,0) -> 30 | M14: =VLOOKUP(C14,Sheet8!$A$5:$L$22,12,0) -> 90 | N14: =VLOOKUP(C14,Sheet8!$A$5:$K$20,11,0) -> 90 | O14: =VLOOKUP(C14,Sheet8!$A$5:$J$20,10,0) -> 0 | P14: =VLOOKUP(C14,Sheet8!$A$5:$I$20,9,0) -> 70 | Q14: =VLOOKUP(C14,Sheet8!$A$5:$H$20,8,0) -> 240 | R14: =VLOOKUP(C14,Sheet8!$A$5:$G$21,7,0) -> 88 | S14: =VLOOKUP(C14,Sheet8!$A$5:$F$20,6,0) -> 260 | T14: =VLOOKUP(C14,Sheet8!$A$5:$E$20,5,0) -> 60 | U14: =VLOOKUP(C14,Sheet8!$A$5:$D$20,4,0) -> 168 | V14: =VLOOKUP(C14,Sheet8!$A$5:$C$20,3,0) -> 70 | W14: =VLOOKUP(C14,Sheet8!$A$5:$B$20,2,0) -> 0
C15: MAX UG NEW EV | D15: =+Monthly!AD37 -> 8970 | E15: =+D15/26 -> 345 | F15: =+G15/$I$2 -> 321.8 | G15: =SUM(K15:W15) -> 3218 | I15: =+F15/E15 -> 0.93275362 | J15: =+G15/D15 -> 0.35875139 | K15: =VLOOKUP(C15,Sheet8!$A$5:$N$21,14,0) -> 280 | L15: =VLOOKUP(C15,Sheet8!$A$5:$M$21,13,0) -> 250 | M15: =VLOOKUP(C15,Sheet8!$A$5:$L$22,12,0) -> 200 | N15: =VLOOKUP(C15,Sheet8!$A$5:$K$20,11,0) -> 110 | O15: =VLOOKUP(C15,Sheet8!$A$5:$J$20,10,0) -> 380 | P15: =VLOOKUP(C15,Sheet8!$A$5:$I$20,9,0) -> 328 | Q15: =VLOOKUP(C15,Sheet8!$A$5:$H$20,8,0) -> 180 | R15: =VLOOKUP(C15,Sheet8!$A$5:$G$21,7,0) -> 330 | S15: =VLOOKUP(C15,Sheet8!$A$5:$F$20,6,0) -> 280 | T15: =VLOOKUP(C15,Sheet8!$A$5:$E$20,5,0) -> 338 | U15: =VLOOKUP(C15,Sheet8!$A$5:$D$20,4,0) -> 186 | V15: =VLOOKUP(C15,Sheet8!$A$5:$C$20,3,0) -> 150 | W15: =VLOOKUP(C15,Sheet8!$A$5:$B$20,2,0) -> 206
C16: FRONT MUDGARD GOGO | D16: =+D15 -> 8970 | E16: =+D16/26 -> 345 | F16: =+G16/$I$2 -> 357.6 | G16: =SUM(K16:W16) -> 3576 | H16: =+G16-G15 -> 358 | I16: =+F16/E16 -> 1.0365217 | J16: =+G16/D16 -> 0.39866221 | K16: =VLOOKUP(C16,Sheet8!$A$5:$N$21,14,0) -> 131 | L16: =VLOOKUP(C16,Sheet8!$A$5:$M$21,13,0) -> 190 | M16: =VLOOKUP(C16,Sheet8!$A$5:$L$22,12,0) -> 430 | N16: =VLOOKUP(C16,Sheet8!$A$5:$K$20,11,0) -> 0 | O16: =VLOOKUP(C16,Sheet8!$A$5:$J$20,10,0) -> 300 | P16: =VLOOKUP(C16,Sheet8!$A$5:$I$20,9,0) -> 430 | Q16: =VLOOKUP(C16,Sheet8!$A$5:$H$20,8,0) -> 370 | R16: =VLOOKUP(C16,Sheet8!$A$5:$G$21,7,0) -> 360 | S16: =VLOOKUP(C16,Sheet8!$A$5:$F$20,6,0) -> 230 | T16: =VLOOKUP(C16,Sheet8!$A$5:$E$20,5,0) -> 375 | U16: =VLOOKUP(C16,Sheet8!$A$5:$D$20,4,0) -> 280 | V16: =VLOOKUP(C16,Sheet8!$A$5:$C$20,3,0) -> 280 | W16: =VLOOKUP(C16,Sheet8!$A$5:$B$20,2,0) -> 200
C17: CRADEL | D17: =+Monthly!AD57 -> 8890 | E17: =+D17/26 -> 341.92308 | F17: =+G17/$I$2 -> 271.6 | G17: =SUM(K17:W17) -> 2716 | H17: =+(G17-E17)/I2 -> 237.40769 | I17: =+F17/E17 -> 0.79433071 | J17: =+G17/D17 -> 0.30551181 | K17: =VLOOKUP(C17,Sheet8!$A$5:$N$21,14,0) -> 192 | L17: =VLOOKUP(C17,Sheet8!$A$5:$M$21,13,0) -> 288 | M17: =VLOOKUP(C17,Sheet8!$A$5:$L$22,12,0) -> 268 | N17: =VLOOKUP(C17,Sheet8!$A$5:$K$20,11,0) -> 0 | O17: =VLOOKUP(C17,Sheet8!$A$5:$J$20,10,0) -> 192 | P17: =VLOOKUP(C17,Sheet8!$A$5:$I$20,9,0) -> 240 | Q17: =VLOOKUP(C17,Sheet8!$A$5:$H$20,8,0) -> 240 | R17: =VLOOKUP(C17,Sheet8!$A$5:$G$21,7,0) -> 192 | S17: =VLOOKUP(C17,Sheet8!$A$5:$F$20,6,0) -> 240 | T17: =VLOOKUP(C17,Sheet8!$A$5:$E$20,5,0) -> 288 | U17: =VLOOKUP(C17,Sheet8!$A$5:$D$20,4,0) -> 288 | V17: =VLOOKUP(C17,Sheet8!$A$5:$C$20,3,0) -> 288 | W17: =VLOOKUP(C17,Sheet8!$A$5:$B$20,2,0) -> 0
C18: INNER DOOR | D18: =+D14+D15 -> 13906 | E18: =+D18/26 -> 534.84615 | F18: =+G18/$I$2 -> 355.7 | G18: =SUM(K18:W18) -> 3557 | H18: =+G18-(G14+G15) -> -1027 | K18: 510 | L18: 424 | M18: 0 | N18: 0 | O18: 0 | P18: 210 | Q18: 0 | R18: 1221 | S18: 0 | T18: 931 | U18: 261 | V18: 0 | W18: 0
C19: ENG BKT | D19: =+Monthly!AD56 -> 3043 | E19: =+D19/26 -> 117.03846 | F19: =+G19/$I$2 -> 113.2 | G19: =SUM(K19:W19) -> 1132 | H19: =+G19-E19/I2 -> 1120.2962 | I19: =+F19/E19 -> 0.96720342 | J19: =+G19/D19 -> 0.37200131 | K19: =VLOOKUP(C19,Sheet8!$A$5:$N$21,14,0) -> 0 | L19: =VLOOKUP(C19,Sheet8!$A$5:$M$21,13,0) -> 400 | M19: =VLOOKUP(C19,Sheet8!$A$5:$L$22,12,0) -> 324 | N19: =VLOOKUP(C19,Sheet8!$A$5:$K$20,11,0) -> 0 | O19: 0 | P19: =VLOOKUP(C19,Sheet8!$A$5:$I$20,9,0) -> 84 | Q19: =VLOOKUP(C19,Sheet8!$A$5:$H$20,8,0) -> 84 | R19: =VLOOKUP(C19,Sheet8!$A$5:$G$21,7,0) -> 0 | S19: =VLOOKUP(C19,Sheet8!$A$5:$F$20,6,0) -> 84 | T19: =VLOOKUP(C19,Sheet8!$A$5:$E$20,5,0) -> 0 | U19: =VLOOKUP(C19,Sheet8!$A$5:$D$20,4,0) -> 72 | V19: =VLOOKUP(C19,Sheet8!$A$5:$C$20,3,0) -> 84 | W19: =VLOOKUP(C19,Sheet8!$A$5:$B$20,2,0) -> 0
C20: LOGISTICS | D20: 141241 | E20: =+D20/26 -> 5432.3462 | F20: =+G20/$I$2 -> 4221 | G20: =SUM(K20:W20) -> 42210 | I20: =+F20/E20 -> 0.77701234 | J20: =+G20/D20 -> 0.2988509 | K20: =VLOOKUP(C20,Sheet8!$A$5:$N$21,14,0) -> 15270 | L20: =VLOOKUP(C20,Sheet8!$A$5:$M$21,13,0) -> 3600 | M20: =VLOOKUP(C20,Sheet8!$A$5:$L$22,12,0) -> 2000 | N20: =VLOOKUP(C20,Sheet8!$A$5:$K$20,11,0) -> 0 | O20: 0 | P20: =VLOOKUP(C20,Sheet8!$A$5:$I$20,9,0) -> 2000 | Q20: =VLOOKUP(C20,Sheet8!$A$5:$H$20,8,0) -> 2084 | R20: =VLOOKUP(C20,Sheet8!$A$5:$G$21,7,0) -> 0 | S20: =VLOOKUP(C20,Sheet8!$A$5:$F$20,6,0) -> 84 | T20: =VLOOKUP(C20,Sheet8!$A$5:$E$20,5,0) -> 2000 | U20: =VLOOKUP(C20,Sheet8!$A$5:$D$20,4,0) -> 72 | V20: =VLOOKUP(C20,Sheet8!$A$5:$C$20,3,0) -> 15100 | W20: =VLOOKUP(C20,Sheet8!$A$5:$B$20,2,0) -> 0
C21: Re Side Door | D21: =+Monthly!AD70 -> 33800 | E21: =+D21/26 -> 1300 | F21: =+G21/$I$2 -> 1040 | G21: =SUM(K21:W21) -> 10400 | H21: =+G21-G5 -> 2195 | I21: =+F21/E21 -> 0.8 | J21: =+G21/D21 -> 0.30769231 | K21: =VLOOKUP(C21,Sheet8!$A$5:$N$21,14,0) -> 960 | L21: =VLOOKUP(C21,Sheet8!$A$5:$M$21,13,0) -> 720 | M21: =VLOOKUP(C21,Sheet8!$A$5:$L$22,12,0) -> 960 | N21: =VLOOKUP(C21,Sheet8!$A$5:$K$20,11,0) -> 0 | O21: =VLOOKUP(C21,Sheet8!$A$5:$J$20,10,0) -> 960 | P21: =VLOOKUP(C21,Sheet8!$A$5:$I$20,9,0) -> 960 | Q21: =VLOOKUP(C21,Sheet8!$A$5:$H$20,8,0) -> 1200 | R21: =VLOOKUP(C21,Sheet8!$A$5:$G$21,7,0) -> 1120 | S21: =VLOOKUP(C21,Sheet8!$A$5:$F$20,6,0) -> 1120 | T21: =VLOOKUP(C21,Sheet8!$A$5:$E$20,5,0) -> 720 | U21: =VLOOKUP(C21,Sheet8!$A$5:$D$20,4,0) -> 720 | V21: =VLOOKUP(C21,Sheet8!$A$5:$C$20,3,0) -> 960 | W21: =VLOOKUP(C21,Sheet8!$A$5:$B$20,2,0) -> 0
C22: Total | D22: =SUM(D5:D21) -> 616795.68 | E22: =SUM(E5:E21) -> 23722.911 | G22: =SUM(G5:G21) -> 205629 | I22: =AVERAGE(I5:I21) -> 0.83980677 | J22: =AVERAGE(J5:J21) -> 0.30862084 | P22: 0
E65459: =+D65459/25 -> 0

Sheet Monthly
A1: 3 Wh Production Plan - May - 26
D2: Month | G2: Prod In 3WH plant | M2: Prod in 4WH plant | Q2: Total Production plan
A3: Sr.No. | B3: Model | C3: Line | D3: Production Requirement | G3: Prod Plan | H3: Week 1--- 8 Days | I3: Week 2--- 6 Days | J3: Week 3--- 6 Days | K3: Week 4--- 6 Days | L3: Monthly Req. In 3WH plant | M3: Maxima & Cargo in 4WH Line (prod Plan) | N3: Monthly Req. In 4WH plant | O3: Net Vehicles production to be plan in May - 26 | W3: re styling
D4: Dom | E4: Export | F4: Total | H4: (2 to 9) | I4: (11 to 16) | J4: (18 to 23) | K4: (25 to 30) | V4: Total | W4: Yesh 50% | X4: Laxmi 50%
D5: BS VI | E5: BS IV | O5: BS IV | P5: BS VI | Q5: Total | S5: Veh. Type | T5: BS VI | U5: BS IV
A6: 1 | B6: RE 4S PETROL | C6: D | E6: 15050 | F6: =SUM(D6:E6) -> 15050 | G6: =F6/26 -> 578.84615 | H6: =$G6*3 -> 1736.5385 | I6: =$G6*6 -> 3473.0769 | J6: =$G6*6 -> 3473.0769 | K6: =$G6*6 -> 3473.0769 | L6: =F6 -> 15050 | O6: =L6 -> 15050 | Q6: =L6+N6 -> 15050 | S6: Re Petrol | T6: =+Q6+Q15+Q12 -> 26292 | V6: =+T6 -> 26292 | W6: =+Z6 -> 19456.08 | X6: =+AA6 -> 6835.92 | Z6: =+T6*74/100 -> 19456.08 | AA6: =T6*26/100 -> 6835.92
A7: 2 | B7: RE 4S CNG Bi-fuel | D7: 0 | E7: 900 | F7: =SUM(D7:E7) -> 900 | G7: =F7/26 -> 34.615385 | H7: =$G7*3 -> 103.84615 | I7: =$G7*6 -> 207.69231 | J7: =$G7*6 -> 207.69231 | K7: =$G7*6 -> 207.69231 | L7: =F7 -> 900 | O7: =E7 -> 900 | P7: =D7 -> 0 | Q7: =L7+N7 -> 900 | S7: Re CNG | T7: =+Q7+Q8+Q9+Q10+Q11 -> 17688 | V7: =+T7 -> 17688 | W7: =+Z7 -> 3537.6 | X7: =+AA7 -> 14150.4 | Z7: =V7*20/100 -> 3537.6 | AA7: =T7*80/100 -> 14150.4
A8: 3 | B8: RE 4S CNG Bi-fuel OBD 2B | D8: 13104 | E8: 608 | F8: =SUM(D8:E8) -> 13712 | G8: =F8/26 -> 527.38462 | H8: =$G8*3 -> 1582.1538 | I8: =$G8*6 -> 3164.3077 | J8: =$G8*6 -> 3164.3077 | K8: =$G8*6 -> 3164.3077 | L8: =F8 -> 13712 | O8: =E8 -> 608 | P8: =D8 -> 13104 | Q8: =L8+N8 -> 13712 | S8: PG MF 2s | T8: =+Q13+Q16 -> 748 | V8: =+T8 -> 748 | X8: =+V8 -> 748 | AA8: =T8 -> 748
A9: 4 | B9: RE 4S LPG MF OBD 2B | D9: 170 | F9: =SUM(D9:E9) -> 170 | G9: =F9/26 -> 6.5384615 | H9: =$G9*3 -> 19.615385 | I9: =$G9*6 -> 39.230769 | J9: =$G9*6 -> 39.230769 | K9: =$G9*6 -> 39.230769 | L9: =F9 -> 170 | P9: =D9 -> 170 | Q9: =L9+N9 -> 170 | S9: Re Disel | T9: =+Q19 -> 1231 | V9: =+T9 -> 1231 | W9: =+V9 -> 1231 | X9: 0 | Z9: =T9 -> 1231
A10: 5 | B10: RE 4S LPG Bi-fuel | D10: 0 | E10: 800 | F10: =SUM(D10:E10) -> 800 | G10: =F10/26 -> 30.769231 | H10: =$G10*3 -> 92.307692 | I10: =$G10*6 -> 184.61538 | J10: =$G10*6 -> 184.61538 | K10: =$G10*6 -> 184.61538 | L10: =F10 -> 800 | O10: =E10 -> 800 | P10: =D10 -> 0 | Q10: =L10+N10 -> 800 | S10: EV GOGO | T10: =+Q17+Q18 -> 2596 | V10: =+T10 -> 2596 | X10: =+V10 -> 2596 | AA10: =T10 -> 2596
A11: 6 | B11: RE 4S LPG Bi-fuel OBD 2B | D11: 430 | E11: =458+1155+63 -> 1676 | F11: =SUM(D11:E11) -> 2106 | G11: =F11/26 -> 81 | H11: =$G11*3 -> 243 | I11: =$G11*6 -> 486 | J11: =$G11*6 -> 486 | K11: =$G11*6 -> 486 | L11: =F11 -> 2106 | O11: =E11 -> 1676 | P11: =D11 -> 430 | Q11: =L11+N11 -> 2106 | S11: Total | T11: =SUM(T6:T10) -> 48555 | U11: =SUM(U6:U10) -> 0 | V11: =+T11 -> 48555 | W11: =+W6+W7+W8+W9+W10 -> 24224.68 | X11: =+X6+X7+X8+X9+X10 -> 24330.32 | Z11: =SUM(Z6:Z10) -> 24224.68 | AA11: =SUM(AA6:AA10) -> 24330.32
A12: 7 | B12: RE 4S PETROL OBD 2B | D12: 336 | F12: =SUM(D12:E12) -> 336 | G12: =F12/26 -> 12.923077 | H12: =$G12*3 -> 38.769231 | I12: =$G12*6 -> 77.538462 | J12: =$G12*6 -> 77.538462 | K12: =$G12*6 -> 77.538462 | L12: =F12 -> 336 | P12: =D12 -> 336 | Q12: =L12+N12 -> 336 | S12: Re max UG | T12: =+Q21+Q22+Q23+Q24+Q25+Q26 -> 4936 | V12: =+T12 -> 4936 | Z12: =V11/2 -> 24277.5 | AA12: =Z12 -> 24277.5
A13: 8 | B13: RE LPG 2S ES | D13: 0 | E13: 462 | F13: =SUM(D13:E13) -> 462 | G13: =F13/26 -> 17.769231 | H13: =$G13*3 -> 53.307692 | I13: =$G13*6 -> 106.61538 | J13: =$G13*6 -> 106.61538 | K13: =$G13*6 -> 106.61538 | L13: =F13 -> 462 | O13: =E13 -> 462 | P13: =D13 -> 0 | Q13: =L13+N13 -> 462 | S13: Re max UG EV GOGO | T13: =+Q28+Q27 -> 8970 | V13: =+T13 -> 8970
B14: Total D Line | D14: =SUM(D6:D13) -> 14040 | E14: =SUM(E6:E13) -> 19496 | F14: =SUM(F6:F13) -> 33536 | G14: =SUM(G6:G13) -> 1289.8462 | H14: =SUM(H6:H13) -> 3869.5385 | I14: =SUM(I6:I13) -> 7739.0769 | J14: =SUM(J6:J13) -> 7739.0769 | K14: =SUM(K6:K13) -> 7739.0769 | L14: =SUM(L6:L13) -> 33536 | O14: =SUM(O6:O13) -> 19496 | P14: =SUM(P6:P13) -> 14040 | Q14: =SUM(Q6:Q13) -> 33536 | S14: Max Wider | T14: =+Q20+Q30+Q31 -> 5469 | V14: =+T14 -> 5469
A15: 1 | B15: RE 4S PETROL | C15: E | E15: =25956-15050 -> 10906 | F15: =SUM(D15:E15) -> 10906 | G15: =F15/26+200 -> 619.46154 | H15: =$G15*3 -> 1858.3846 | I15: =$G15*6 -> 3716.7692 | J15: =$G15*6 -> 3716.7692 | K15: =$G15*6 -> 3716.7692 | L15: =F15 -> 10906 | O15: =L15 -> 10906 | P15: =D15 -> 0 | Q15: =L15+N15 -> 10906 | S15: Max Wider EV | T15: =+Q29 -> 350 | V15: =+T15 -> 350
A16: 2 | B16: RE PET 2S NES/ES EXP | E16: 286 | F16: =SUM(D16:E16) -> 286 | G16: =F16/26 -> 11 | H16: =$G16*3 -> 33 | I16: =$G16*6 -> 66 | J16: =$G16*6 -> 66 | K16: =$G16*6 -> 66 | L16: =F16 -> 286 | O16: =L16 -> 286 | P16: =D16 -> 0 | Q16: =L16+N16 -> 286 | S16: gc Cabin | T16: =+Q32+Q33+Q34+Q35+Q36+Q37+Q38+Q39+Q40 -> 6860 | V16: =+T16 -> 6860
A17: 3 | B17: RE EV 9.2 Kwh WEGO (Wider scudo) | D17: 1399 | E17: 735 | F17: =SUM(D17:E17) -> 2134 | G17: =F17/26 -> 82.076923 | H17: =$G17*3 -> 246.23077 | I17: =$G17*6 -> 492.46154 | J17: =$G17*6 -> 492.46154 | K17: =$G17*6 -> 492.46154 | L17: =F17 -> 2134 | O17: =E17 -> 735 | P17: =D17 -> 1399 | Q17: =L17+N17 -> 2134 | S17: E RIKI | T17: =+Q41+Q42+Q43 -> 544
A18: 4 | B18: RE EV 12.2 Kwh WEGO (Wider scudo) | D18: 462 | F18: =SUM(D18:E18) -> 462 | G18: =F18/26 -> 17.769231 | H18: =$G18*3 -> 53.307692 | I18: =$G18*6 -> 106.61538 | J18: =$G18*6 -> 106.61538 | K18: =$G18*6 -> 106.61538 | L18: =F18 -> 462 | P18: =D18 -> 462 | Q18: =L18+N18 -> 462
A19: 5 | B19: RE DIESEL OBD 2B | D19: 1231 | F19: =SUM(D19:E19) -> 1231 | G19: =F19/26 -> 47.346154 | H19: =$G19*3 -> 142.03846 | I19: =$G19*6 -> 284.07692 | J19: =$G19*6 -> 284.07692 | K19: =$G19*6 -> 284.07692 | L19: =F19 -> 1231 | O19: =E19 -> 0 | P19: =L19 -> 1231 | Q19: =L19+N19 -> 1231
A20: 6 | B20: BAJAJ MAXIMA X WIDE DIESEL OBD2B | D20: 3652 | F20: =SUM(D20:E20) -> 3652 | H20: =$G20*3 -> 0 | I20: =$G20*6 -> 0 | J20: =$G20*6 -> 0 | K20: =$G20*6 -> 0 | L20: 0 | M20: =N20/26 -> 140.46154 | N20: =F20 -> 3652 | P20: =D20 -> 3652 | Q20: =N20 -> 3652
A21: 7 | B21: BAJAJ MAXIMA Z CNG Bi-fuel OBD 2B | D21: 3622 | F21: =SUM(D21:E21) -> 3622 | H21: =$G21*3 -> 0 | I21: =$G21*6 -> 0 | J21: =$G21*6 -> 0 | K21: =$G21*6 -> 0 | L21: 0 | M21: =N21/26 -> 139.30769 | N21: =F21 -> 3622 | P21: =N21 -> 3622 | Q21: =N21 -> 3622 | T21: =+T12+T14+T16 -> 17265
A22: 8 | B22: BAJAJ MAXIMA Z LPG MF OBD 2B | D22: 8 | F22: =SUM(D22:E22) -> 8 | H22: =$G22*3 -> 0 | I22: =$G22*6 -> 0 | J22: =$G22*6 -> 0 | K22: =$G22*6 -> 0 | L22: 0 | M22: =N22/26 -> 0.30769231 | N22: =F22 -> 8 | P22: =N22 -> 8 | Q22: =N22 -> 8
A23: 9 | B23: BAJAJ MAXIMA Z LPG Bi-fuel | D23: 0 | E23: 120 | F23: =SUM(D23:E23) -> 120 | H23: =$G23*3 -> 0 | I23: =$G23*6 -> 0 | J23: =$G23*6 -> 0 | K23: =$G23*6 -> 0 | L23: 0 | M23: =N23/26 -> 4.6153846 | N23: =F23 -> 120 | O23: =E23 -> 120 | P23: 0 | Q23: =N23 -> 120
A24: 10 | B24: BAJAJ MAXIMA Z LPG Bi-fuel OBD 2B | D24: 293 | F24: =SUM(D24:E24) -> 293 | H24: =$G24*3 -> 0 | I24: =$G24*6 -> 0 | J24: =$G24*6 -> 0 | K24: =$G24*6 -> 0 | L24: 0 | M24: =N24/26 -> 11.269231 | N24: =F24 -> 293 | P24: =N24 -> 293 | Q24: =N24 -> 293
A25: 11 | B25: BAJAJ MAXIMA Z DIESEL OBD 2B | D25: 581 | F25: =SUM(D25:E25) -> 581 | H25: =$G25*3 -> 0 | I25: =$G25*6 -> 0 | J25: =$G25*6 -> 0 | K25: =$G25*6 -> 0 | L25: 0 | M25: =N25/26 -> 22.346154 | N25: =F25 -> 581 | P25: =N25 -> 581 | Q25: =N25 -> 581
A26: 12 | B26: BAJAJ MAXIMA Z PET | D26: 0 | E26: 312 | F26: =SUM(D26:E26) -> 312 | H26: =$G26*3 -> 0 | I26: =$G26*6 -> 0 | J26: =$G26*6 -> 0 | K26: =$G26*6 -> 0 | L26: 0 | M26: =N26/26 -> 12 | N26: =F26 -> 312 | O26: =E26 -> 312 | P26: 0 | Q26: =N26 -> 312
A27: 13 | B27: WEGO P7009 | D27: 805 | F27: =SUM(D27:E27) -> 805 | H27: =$G27*3 -> 0 | I27: =$G27*6 -> 0 | J27: =$G27*6 -> 0 | K27: =$G27*6 -> 0 | L27: 0 | M27: =N27/26 -> 30.961538 | N27: =F27 -> 805 | O27: =E27 -> 0 | P27: =N27 -> 805 | Q27: =N27 -> 805 | AA27: 3wh Production plan May 2026
A28: 14 | B28: BAJAJA MAXIMA Z EV WEGO P7012 (Wider scudo) | D28: 8165 | F28: =SUM(D28:E28) -> 8165 | H28: =$G28*3 -> 0 | I28: =$G28*6 -> 0 | J28: =$G28*6 -> 0 | K28: =$G28*6 -> 0 | L28: 0 | M28: =N28/26 -> 314.03846 | N28: =F28 -> 8165 | O28: =E28 -> 0 | P28: =N28 -> 8165 | Q28: =N28 -> 8165
A29: 15 | B29: BAJAJ MAXIMA X WIDE WEGO P9018 | D29: 350 | F29: =SUM(D29:E29) -> 350 | H29: =$G29*3 -> 0 | I29: =$G29*6 -> 0 | J29: =$G29*6 -> 0 | K29: =$G29*6 -> 0 | L29: 0 | M29: =N29/26 -> 13.461538 | N29: =F29 -> 350 | P29: =N29 -> 350 | Q29: =N29 -> 350
A30: 16 | B30: BAJAJ MAXIMA X WIDE CNG Bi-fuel OBD 2B | D30: 1813 | F30: =SUM(D30:E30) -> 1813 | H30: =$G30*3 -> 0 | I30: =$G30*6 -> 0 | J30: =$G30*6 -> 0 | K30: =$G30*6 -> 0 | L30: 0 | M30: =N30/26 -> 69.730769 | N30: =F30 -> 1813 | P30: =N30 -> 1813 | Q30: =N30 -> 1813 | AD30: Working Days | AE30: 26
A31: 17 | B31: BAJAJ MAXIMA X WIDE LPG Bi-fuel OBD 2B | D31: 4 | F31: =SUM(D31:E31) -> 4 | H31: =$G31*3 -> 0 | I31: =$G31*6 -> 0 | J31: =$G31*6 -> 0 | K31: =$G31*6 -> 0 | L31: 0 | M31: =N31/26 -> 0.15384615 | N31: =F31 -> 4 | P31: =N31 -> 4 | Q31: =N31 -> 4 | AA31: Line | AB31: Material | AC31: Description | AD31: Production plan | AE31: Per day
A32: 18 | B32: BAJAJ MAXIMA C PET | D32: 0 | E32: 232 | F32: =SUM(D32:E32) -> 232 | H32: =$G32*3 -> 0 | I32: =$G32*6 -> 0 | J32: =$G32*6 -> 0 | K32: =$G32*6 -> 0 | L32: 0 | M32: =N32/26 -> 8.9230769 | N32: =F32 -> 232 | O32: =E32 -> 232 | P32: 0 | Q32: =N32 -> 232 | AA32: RE Styling | AB32: 1502020125 | AC32: 52AF1050 BODY ASSLY RE AIR COOLED BI-FUE | AD32: =+W7 -> 3537.6 | AE32: =+AD32/$AE$30 -> 136.06154
A33: 19 | B33: BAJAJ MAXIMA C CNG Bi-fuel Longer tray OBD 2B | D33: 2504 | F33: =SUM(D33:E33) -> 2504 | H33: =$G33*3 -> 0 | I33: =$G33*6 -> 0 | J33: =$G33*6 -> 0 | K33: =$G33*6 -> 0 | L33: 0 | M33: =N33/26 -> 96.307692 | N33: =F33 -> 2504 | P33: =N33 -> 2504 | Q33: =N33 -> 2504 | AB33: 1502020101 | AC33: 52BA0852 ASSLY BODY COMPACT DIESEL | AD33: =+W9 -> 1231 | AE33: =+AD33/$AE$30 -> 47.346154
A34: 20 | B34: BAJAJ MAXIMA C CNG Bi-fuel shorter tray OBD 2B | D34: 0 | F34: =SUM(D34:E34) -> 0 | H34: =$G34*3 -> 0 | I34: =$G34*6 -> 0 | J34: =$G34*6 -> 0 | K34: =$G34*6 -> 0 | L34: 0 | M34: =N34/26 -> 0 | N34: =F34 -> 0 | O34: =E34 -> 0 | P34: =N34 -> 0 | Q34: =N34 -> 0 | AB34: 1502020104 | AC34: AA231532 BODY ASSLY PETROL | AD34: =+W6 -> 19456.08 | AE34: =+AD34/$AE$30 -> 748.31077
A35: 21 | B35: BAJAJ MAXIMA C EV 9.2 Kwh LT WEGO | D35: 48 | F35: =SUM(D35:E35) -> 48 | H35: =$G35*3 -> 0 | I35: =$G35*6 -> 0 | J35: =$G35*6 -> 0 | K35: =$G35*6 -> 0 | L35: 0 | M35: =N35/26 -> 1.8461538 | N35: =F35 -> 48 | P35: =N35 -> 48 | Q35: =N35 -> 48 | AC35: Total | AD35: =SUM(AD32:AD34) -> 24224.68 | AE35: =SUM(AE32:AE34) -> 931.71846
A36: 22 | B36: BAJAJ MAXIMA C EV 12.2 Kwh WEGO | D36: 570 | F36: =SUM(D36:E36) -> 570 | H36: =$G36*3 -> 0 | I36: =$G36*6 -> 0 | J36: =$G36*6 -> 0 | K36: =$G36*6 -> 0 | L36: 0 | M36: =N36/26 -> 21.923077 | N36: =F36 -> 570 | P36: =N36 -> 570 | Q36: =N36 -> 570 | AA36: Re MAX UG NEW | AB36: 1502020074 | AC36: 52AZ0184 BODY ASSLY MAX Z WTH REGU. HOOD | AD36: =+T12 -> 4936 | AE36: =+AD36/$AE$30 -> 189.84615
A37: 23 | B37: BAJAJ MAXIMA C LPG | D37: 0 | E37: 80 | F37: =SUM(D37:E37) -> 80 | H37: =$G37*3 -> 0 | I37: =$G37*6 -> 0 | J37: =$G37*6 -> 0 | K37: =$G37*6 -> 0 | L37: 0 | M37: =N37/26 -> 3.0769231 | N37: =F37 -> 80 | O37: =E37 -> 80 | P37: 0 | Q37: =N37 -> 80 | AB37: 1502020122 | AC37: 52AH0692 BODY ASSLY MAXIMA Z EV | AD37: =+T13 -> 8970 | AE37: =+AD37/$AE$30 -> 345
A38: 24 | B38: BAJAJ MAXIMA C DIESEL | D38: 0 | F38: =SUM(D38:E38) -> 0 | H38: =$G38*3 -> 0 | I38: =$G38*6 -> 0 | J38: =$G38*6 -> 0 | K38: =$G38*6 -> 0 | L38: =SUM(H38:K38)*0.963 -> 0 | M38: =N38/26 -> 0 | N38: =F38 -> 0 | O38: =E38 -> 0 | P38: =D38 -> 0 | Q38: =L38+N38 -> 0 | AD38: =+AD37+AD36 -> 13906 | AE38: =+AE36+AE37 -> 534.84615
A39: 25 | B39: BAJAJ MAXIMA C DIESEL Longer tray OBD2B | D39: 3206 | E39: 120 | F39: =SUM(D39:E39) -> 3326 | H39: =$G39*3 -> 0 | I39: =$G39*6 -> 0 | J39: =$G39*6 -> 0 | K39: =$G39*6 -> 0 | L39: 0 | M39: =N39/26 -> 127.92308 | N39: =F39 -> 3326 | O39: =E39 -> 120 | P39: =D39 -> 3206 | Q39: =N39 -> 3326 | AA39: MAXIMA HD Wider | AB39: 1502020102 | AC39: AT211332 BODY ASSLY MAXIMA HD | AD39: =+T14 -> 5469 | AE39: =+AD39/$AE$30 -> 210.34615
A40: 26 | B40: BAJAJ MAXIMA C DIESEL shorter tray OBD 2B | D40: 100 | F40: =SUM(D40:E40) -> 100 | H40: =$G40*3 -> 0 | I40: =$G40*6 -> 0 | J40: =$G40*6 -> 0 | K40: =$G40*6 -> 0 | L40: 0 | M40: =N40/26 -> 3.8461538 | N40: =F40 -> 100 | O40: =E40 -> 0 | P40: =D40 -> 100 | Q40: =N40 -> 100 | AB40: 1502020117 | AC40: 52BK0023 BODY ASSLY MAXIMA HD EV | AD40: =+T15 -> 350 | AE40: =+AD40/$AE$30 -> 13.461538
...

Sheet Sheet3
B3: 5356
B4: 5000

Sheet Sheet4
A4: Material | B4: Line
A5: 1502040194 | B5: CRADEL
A6: 1502040198 | B6: CRADEL
A7: 1502040199 | B7: CRADEL
A8: 1502040114 | B8: DASH BOARD
A9: 1502040267 | B9: DASH BOARD
A10: 1402010204 | B10: ENG BKT
A11: 1502010023 | B11: ENG BKT
A12: 1502010024 | B12: ENG BKT
A13: 1502040068 | B13: ENG BKT
A14: 1502040127 | B14: ENG BKT
A15: 1502040216 | B15: FRONT MUDGAURD
A16: 1502040217 | B16: FRONT MUDGARD GOGO
... A72: 1104040829 | B72: INNER DOOR

Sheet Sheet8
A3: Sum of Billing Qty | B3: Billling Date
A4: Line | B4: 01.05.2026 | C4: 02.05.2026 | D4: 03.05.2026 | E4: 04.05.2026 | F4: 05.05.2026 | G4: 06.05.2026 | H4: 07.05.2026 | I4: 08.05.2026 | J4: 09.05.2026 | K4: 10.05.2026 | L4: 11.05.2026 | M4: 12.05.2026 | N4: 13.05.2026 | O4: Grand Total
A5: CRADEL | C5: 288 | D5: 288 | E5: 288 | F5: 240 | G5: 192 | H5: 240 | I5: 240 | J5: 192 | L5: 268 | M5: 288 | N5: 192 | O5: 2716
A6: DASH BOARD | B6: 816 | C6: 1660 | D6: 1240 | E6: 2362 | F6: 2428 | G6: 1224 | H6: 2448 | I6: 2152 | J6: 1792 | K6: 920 | L6: 2038 | M6: 2118 | N6: 2082 | O6: 23280
A7: ENG BKT | C7: 84 | D7: 72 | F7: 84 | H7: 84 | I7: 84 | J7: -3 | L7: 324 | M7: 400 | O7: 1129
A8: FRONT MUDGARD GOGO | B8: 200 | C8: 280 | D8: 280 | E8: 375 | F8: 230 | G8: 360 | H8: 370 | I8: 430 | J8: 300 | L8: 430 | M8: 190 | N8: 131 | O8: 3576
A9: FRONT MUDGAURD | C9: 960 | D9: 1280 | E9: 1660 | F9: 2080 | G9: 2139 | H9: 1280 | I9: 2350 | J9: 2080 | L9: 2410 | M9: 2120 | N9: 2204 | O9: 20563
A10: LOGISTICS | C10: 15100 | D10: 72 | E10: 2000 | F10: 84 | H10: 2084 | I10: 2000 | J10: -3 | L10: 2000 | M10: 3600 | N10: 15270 | O10: 42207
A11: MAX UG NEW | C11: 70 | D11: 168 | E11: 60 | F11: 260 | G11: 88 | H11: 240 | I11: 70 | K11: 90 | L11: 90 | M11: 30 | N11: 200 | O11: 1366
A12: MAX UG NEW EV | B12: 206 | C12: 150 | D12: 186 | E12: 338 | F12: 280 | G12: 330 | H12: 180 | I12: 328 | J12: 380 | K12: 110 | L12: 200 | M12: 250 | N12: 280 | O12: 3218
A13: MAXIMA HD | C13: 172 | D13: 24 | E13: 138 | F13: 144 | G13: 90 | H13: 158 | I13: 124 | J13: 42 | L13: 230 | M13: 152 | N13: 144 | O13: 1418
A14: Re Side Door | C14: 960 | D14: 720 | E14: 720 | F14: 1120 | G14: 1120 | H14: 1200 | I14: 960 | J14: 960 | L14: 960 | M14: 720 | N14: 960 | O14: 10400
A15: RE STYLING | B15: 120 | C15: 501 | D15: 630 | E15: 516 | F15: 885 | G15: 822 | H15: 705 | I15: 861 | J15: 846 | K15: 120 | L15: 759 | M15: 633 | N15: 807 | O15: 8205
A16: REAR COVER | C16: 220 | D16: 330 | E16: 520 | F16: 440 | G16: 330 | H16: 330 | I16: 330 | J16: 110 | M16: 440 | N16: 330 | O16: 3380
A17: REAR MUDGAURD | C17: 5184 | D17: 5184 | E17: 4320 | F17: 5184 | G17: 3888 | H17: 4752 | I17: 4320 | J17: 2592 | K17: 2160 | L17: 4320 | M17: 3888 | N17: 3456 | O17: 49248
A18: STARTING HANDLE | C18: 1760 | D18: 720 | E18: 1080 | F18: 1350 | G18: 1620 | H18: 1350 | I18: 1080 | J18: 1079 | L18: 1530 | M18: 1380 | N18: 1080 | O18: 14029
A19: SUPPORT TOP | C19: 2376 | D19: 1688 | E19: 1200 | F19: 2160 | G19: 1688 | H19: 1248 | I19: 1688 | J19: 1200 | L19: 1344 | M19: 916 | N19: 1473 | O19: 16981
A20: DOOR INNER | D20: 931 | E20: 261 | G20: 1221 | I20: 210 | J20: 598 | M20: 510 | N20: 424 | O20: 4155
A21: FRONT MUDGAURD EV | L21: 150 | M21: 100 | N21: 100 | O21: 350
A22: Grand Total | B22: 1342 | C22: 29765 | D22: 13813 | E22: 15838 | F22: 16969 | G22: 15112 | H22: 16669 | I22: 17227 | J22: 12165 | K22: 3400 | L22: 17053 | M22: 17735 | N22: 29133 | O22: 206221

Sheet Sheet2
A1: Plant | B1: Profit Centre | C1: Dist.Channel | D1: Division | E1: Division text | F1: Billing Type | G1: Billing Type Desc | H1: Billing Doc | I1: Accounting Doc | J1: Status | K1: Excise Invoice No | L1: Billling Date | M1: Sales Order No | N1: Sales Doc.Type | O1: Sales Type Text | P1: Cust-PO-No | Q1: Cust-PO-Date | R1: Customer | S1: Customer Name | T1: ShipToParty | U1: STP-Name | V1: Customer TIN No | W1: Material | X1: Material Desc | Y1: Line | Z1: Chapter ID | AA1: Billing Qty | AB1: UoM | AC1: Sale Rate | AD1: Currency | AE1: Basic Value | AF1: Amort.Cost | AG1: Assessable Value | AH1: BED | AI1: ECS | AJ1: HECS | AK1: AED | AL1: Sub Total | AM1: VAT % | AN1: VAT | AO1: CST | AP1: AED | AQ1: TCS | AR1: Srchg on TCS | AS1: ECess on TCS | AT1: SHCess on TCS | AU1: Total Value | AV1: TlCost Rate | AW1: ToolCost Value | AX1: G/L Acoount | AY1: G/L Acoount Desc | AZ1: Gross-Wt | BA1: Net-Wt | BB1: Scrap-Wt | BC1: Old-Material | BD1: Mat-Group | BE1: Mat-Group-Name | BF1: RCIA No | BG1: RCIA Date
A2: 1115 | B2: 1115 | C2: 10 | D2: 2 | E2: Three Wheelers | F2: F2 | G2: COMMERCIAL INVOICE | H2: 1526005946 | I2: 1000006208 | L2: 04.05.2026 | M2: 5100001227 | N2: ZSCH | O2: Normal Sales | P2: 4110011319 | Q2: 18.12.2017 | R2: 5000 | S2: BAJAJ AUTO LIMITED (WALUJ) | V2: 27340676530V | W2: 1502020074 | X2: 52AZ0184 BODY ASSLY MAX Z WTH REGU. HOOD | Y2: =VLOOKUP(W2,Sheet4!$A$5:$B$71,2,0) -> MAX UG NEW | Z2: 87082900 | AA2: 10 | AB2: EA | AC2: 9397.5 | AD2: INR | AE2: 93975 | AF2: 0 | AG2: 93975 | AH2: 0 | AI2: 0 | AJ2: 0 | AK2: 0 | AL2: 93975 | AM2: 0 | AN2: 0 | AO2: 0 | AP2: 0 | AQ2: 0 | AR2: 0 | AS2: 0 | AT2: 0 | AU2: 93975 | AV2: 0 | AW2: 0 | AX2: 311000 | AY2: SALE FINISHED GOODS | AZ2: 69.5 | BA2: 69.5 | BB2: 0 | BC2: 52AZ0184 | BD2: 1509 | BE2: FG Body | BF2: 5094107222 | BG2: 05.05.2026
A3: 1115 | B3: 1115 | C3: 10 | D3: 2 | E3: Three Wheelers | F3: F2 | G3: COMMERCIAL INVOICE | H3: 1526005945 | I3: 1000006207 | L3: 04.05.2026 | M3: 5100001227 | N3: ZSCH | O3: Normal Sales | P3: 4110011319 | Q3: 18.12.2017 | R3: 5000 | S3: BAJAJ AUTO LIMITED (WALUJ) | V3: 27340676530V | W3: 1502020074 | X3: 52AZ0184 BODY ASSLY MAX Z WTH REGU. HOOD | Y3: =VLOOKUP(W3,Sheet4!$A$5:$B$71,2,0) -> MAX UG NEW | Z3: 87082900 | AA3: 10 | AB3: EA | AC3: 9397.5 | AD3: INR | AE3: 93975 | AF3: 0 | AG3: 93975 | AH3: 0 | AI3: 0 | AJ3: 0 | AK3: 0 | AL3: 93975 | AM3: 0 | AN3: 0 | AO3: 0 | AP3: 0 | AQ3: 0 | AR3: 0 | AS3: 0 | AT3: 0 | AU3: 93975 | AV3: 0 | AW3: 0 | AX3: 311000 | AY3: SALE FINISHED GOODS | AZ3: 69.5 | BA3: 69.5 | BB3: 0 | BC3: 52AZ0184 | BD3: 1509 | BE3: FG Body | BF3: 5094106025 | BG3: 05.05.2026
A4: 1115 | B4: 1115 | C4: 10 | D4: 2 | E4: Three Wheelers | F4: F2 | G4: COMMERCIAL INVOICE | H4: 1526005947 | I4: 1000006209 | L4: 04.05.2026 | M4: 5100001227 | N4: ZSCH | O4: Normal Sales | P4: 4110011319 | Q4: 18.12.2017 | R4: 5000 | S4: BAJAJ AUTO LIMITED (WALUJ) | V4: 27340676530V | W4: 1502020074 | X4: 52AZ0184 BODY ASSLY MAX Z WTH REGU. HOOD | Y4: =VLOOKUP(W4,Sheet4!$A$5:$B$71,2,0) -> MAX UG NEW | Z4: 87082900 | AA4: 10 | AB4: EA | AC4: 9397.5 | AD4: INR | AE4: 93975 | AF4: 0 | AG4: 93975 | AH4: 0 | AI4: 0 | AJ4: 0 | AK4: 0 | AL4: 93975 | AM4: 0 | AN4: 0 | AO4: 0 | AP4: 0 | AQ4: 0 | AR4: 0 | AS4: 0 | AT4: 0 | AU4: 93975 | AV4: 0 | AW4: 0 | AX4: 311000 | AY4: SALE FINISHED GOODS | AZ4: 69.5 | BA4: 69.5 | BB4: 0 | BC4: 52AZ0184 | BD4: 1509 | BE4: FG Body | BF4: 5094107378 | BG4: 05.05.2026
A5: 1115 | B5: 1115 | C5: 10 | D5: 2 | E5: Three Wheelers | F5: F2 | G5: COMMERCIAL INVOICE | H5: 1526005948 | I5: 1000006210 | L5: 04.05.2026 | M5: 5100001666 | N5: ZSCH | O5: Normal Sales | P5: 4110027035 | Q5: 03.09.2020 | R5: 5000 | S5: BAJAJ AUTO LIMITED (WALUJ) | V5: 27340676530V | W5: 1502020105 | X5: 52AU0123 BODY ASSLY 4S PETROL | Y5: =VLOOKUP(W5,Sheet4!$A$5:$B$71,2,0) -> RE STYLING | Z5: 87082900 | AA5: 15 | AB5: EA | AC5: 6570.77 | AD5: INR | AE5: 98561.55 | AF5: 0 | AG5: 98561.55 | AH5: 0 | AI5: 0 | AJ5: 0 | AK5: 0 | AL5: 98561.55 | AM5: 0 | AN5: 0 | AO5: 0 | AP5: 0 | AQ5: 0 | AR5: 0 | AS5: 0 | AT5: 0 | AU5: 98561.55 | AV5: 0 | AW5: 0 | AX5: 311000 | AY5: SALE FINISHED GOODS | AZ5: 49.75 | BA5: 49.75 | BB5: 0 | BC5: 52AU0123 | BD5: 1509 | BE5: FG Body | BF5: 5094107126 | BG5: 05.05.2026
A6: 1115 | B6: 1115 | C6: 10 | D6: 2 | E6: Three Wheelers | F6: F2 | G6: COMMERCIAL INVOICE | H6: 1526005944 | I6: 1000006206 | L6: 04.05.2026 | M6: 5100001227 | N6: ZSCH | O6: Normal Sales | P6: 4110011319 | Q6: 18.12.2017 | R6: 5000 | S6: BAJAJ AUTO LIMITED (WALUJ) | V6: 27340676530V | W6: 1502020074 | X6: 52AZ0184 BODY ASSLY MAX Z WTH REGU. HOOD | Y6: =VLOOKUP(W6,Sheet4!$A$5:$B$71,2,0) -> MAX UG NEW | Z6: 87082900 | AA6: 10 | AB6: EA | AC6: 9397.5 | AD6: INR | AE6: 93975 | AF6: 0 | AG6: 93975 | AH6: 0 | AI6: 0 | AJ6: 0 | AK6: 0 | AL6: 93975 | AM6: 0 | AN6: 0 | AO6: 0 | AP6: 0 | AQ6: 0 | AR6: 0 | AS6: 0 | AT6: 0 | AU6: 93975 | AV6: 0 | AW6: 0 | AX6: 311000 | AY6: SALE FINISHED GOODS | AZ6: 69.5 | BA6: 69.5 | BB6: 0 | BC6: 52AZ0184 | BD6: 1509 | BE6: FG Body | BF6: 5094107376 | BG6: 05.05.2026
A7: 1115 | B7: 1115 | C7: 10 | D7: 2 | E7: Three Wheelers | F7: F2 | G7: COMMERCIAL INVOICE | H7: 1526005942 | I7: 1000006204 | L7: 04.05.2026 | M7: 5100001928 | N7: ZSCH | O7: Normal Sales | P7: 4110057393 | Q7: 28.11.2024 | R7: 5000 | S7: BAJAJ AUTO LIMITED (WALUJ) | V7: 27340676530V | W7: 1502020122 | X7: 52AH0692 BODY ASSLY MAXIMA Z EV | Y7: =VLOOKUP(W7,Sheet4!$A$5:$B$71,2,0) -> MAX UG NEW EV | Z7: 87082900 | AA7: 10 | AB7: EA | AC7: 9566.51 | AD7: INR | AE7: 95665.1 | AF7: 0 | AG7: 95665.1 | AH7: 0 | AI7: 0 | AJ7: 0 | AK7: 0 | AL7: 95665.1 | AM7: 0 | AN7: 0 | AO7: 0 | AP7: 0 | AQ7: 0 | AR7: 0 | AS7: 0 | AT7: 0 | AU7: 95665.1 | AV7: 0 | AW7: 0 | AX7: 311000 | AY7: SALE FINISHED GOODS | AZ7: 0 | BA7: 61 | BB7: -61 | BC7: 52AH0692 | BD7: 1509 | BE7: FG Body | BF7: 5094104692 | BG7: 04.05.2026
A8: 1115 | B8: 1115 | C8: 10 | D8: 2 | E8: Three Wheelers | F8: F2 | G8: COMMERCIAL INVOICE | H8: 1526005941 | I8: 1000006203 | L8: 04.05.2026 | M8: 5100001636 | N8: ZSCH | O8: Normal Sales | P8: 4110026445 | Q8: 23.07.2020 | R8: 5000 | S8: BAJAJ AUTO LIMITED (WALUJ) | V8: 27340676530V | W8: 1502020104 | X8: AA231532 BODY ASSLY PETROL | Y8: =VLOOKUP(W8,Sheet4!$A$5:$B$71,2,0) -> RE STYLING | Z8: 87082900 | AA8: 6 | AB8: EA | AC8: 6585.55 | AD8: INR | AE8: 39513.3 | AF8: 0 | AG8: 39513.3 | AH8: 0 | AI8: 0 | AJ8: 0 | AK8: 0 | AL8: 39513.3 | AM8: 0 | AN8: 0 | AO8: 0 | AP8: 0 | AQ8: 0 | AR8: 0 | AS8: 0 | AT8: 0 | AU8: 39513.3 | AV8: 0 | AW8: 0 | AX8: 311000 | AY8: SALE FINISHED GOODS | AZ8: 49.75 | BA8: 49.75 | BB8: 0 | BC8: AA231532 | BD8: 1509 | BE8: FG Body | BF8: 5094107251 | BG8: 05.05.2026
A9: 1115 | B9: 1115 | C9: 10 | D9: 2 | E9: Three Wheelers | F9: F2 | G9: COMMERCIAL INVOICE | H9: 1526005940 | I9: 1000006202 | L9: 04.05.2026 | M9: 5100001407 | N9: ZSCH | O9: Normal Sales | P9: 4110019623 | Q9: 06.05.2019 | R9: 5000 | S9: BAJAJ AUTO LIMITED (WALUJ) | V9: 27340676530V | W9: 1502040216 | X9: AA161289_ ASSEMBLY MUDGUARD FRONT | Y9: =VLOOKUP(W9,Sheet4!$A$5:$B$71,2,0) -> FRONT MUDGAURD | Z9: 87082900 | AA9: 960 | AB9: EA | AC9: 174.11 | AD9: INR | AE9: 167145.6 | AF9: 0 | AG9: 167145.6 | AH9: 0 | AI9: 0 | AJ9: 0 | AK9: 0 | AL9: 167145.6 | AM9: 0 | AN9: 0 | AO9: 0 | AP9: 0 | AQ9: 0 | AR9: 0 | AS9: 0 | AT9: 0 | AU9: 167145.6 | AV9: 0 | AW9: 0 | AX9: 311000 | AY9: SALE FINISHED GOODS | AZ9: 2.573 | BA9: 1.491 | BB9: 1.082 | BC9: AA161289 | BD9: 1511 | BE9: FG Loose 3WH | BF9: 5094107252 | BG9: 05.05.2026
A10: 1115 | B10: 1115 | C10: 10 | D10: 2 | E10: Three Wheelers | F10: F2 | G10: COMMERCIAL INVOICE | H10: 1526005939 | I10: 1000006201 | L10: 04.05.2026 | M10: 5100001924 | N10: ZSCH | O10: Normal Sales | P10: 4110055642 | Q10: 09.09.2024 | R10: 5000 | S10: BAJAJ AUTO LIMITED (WALUJ) | V10: 27340676530V | W10: 1502040314 | X10: 52BA0835 RE DOOR ASSLY LH YELLOW | Y10: =VLOOKUP(W10,Sheet4!$A$5:$B$71,2,0) -> Re Side Door | Z10: 87082900 | AA10: 120 | AB10: EA | AC10: 504.46 | AD10: INR | AE10: 60535.2 | AF10: 0 | AG10: 60535.2 | AH10: 0 | AI10: 0 | AJ10: 0 | AK10: 0 | AL10: 60535.2 | AM10: 0 | AN10: 0 | AO10: 0 | AP10: 0 | AQ10: 0 | AR10: 0 | AS10: 0 | AT10: 0 | AU10: 60535.2 | AV10: 0 | AW10: 0 | AX10: 311000 | AY10: SALE FINISHED GOODS | AZ10: 2.27 | BA10: 2.27 | BB10: 0 | BC10: 52BA0835 | BD10: 1511 | BE10: FG Loose 3WH | BF10: 5094113616 | BG10: 05.05.2026
A11: 1115 | B11: 1115 | C11: 10 | D11: 2 | E11: Three Wheelers | F11: F2 | G11: COMMERCIAL INVOICE | H11: 1526005949 | I11: 1000006211 | L11: 04.05.2026 | M11: 5100001666 | N11: ZSCH | O11: Normal Sales | P11: 4110027035 | Q11: 03.09.2020 | R11: 5000 | S11: BAJAJ AUTO LIMITED (WALUJ) | V11: 27340676530V | W11: 1502020105 | X11: 52AU0123 BODY ASSLY 4S PETROL | Y11: =VLOOKUP(W11,Sheet4!$A$5:$B$71,2,0) -> RE STYLING | Z11: 87082900 | AA11: 15 | AB11: EA | AC11: 6570.77 | AD11: INR | AE11: 98561.55 | AF11: 0 | AG11: 98561.55 | AH11: 0 | AI11: 0 | AJ11: 0 | AK11: 0 | AL11: 98561.55 | AM11: 0 | AN11: 0 | AO11: 0 | AP11: 0 | AQ11: 0 | AR11: 0 | AS11: 0 | AT11: 0 | AU11: 98561.55 | AV11: 0 | AW11: 0 | AX11: 311000 | AY11: SALE FINISHED GOODS | AZ11: 49.75 | BA11: 49.75 | BB11: 0 | BC11: 52AU0123 | BD11: 1509 | BE11: FG Body | BF11: 5094107045 | BG11: 05.05.2026
A12: 1115 | B12: 1115 | C12: 10 | D12: 2 | E12: Three Wheelers | F12: F2 | G12: COMMERCIAL INVOICE | H12: 1526005950 | I12: 1000006212 | L12: 04.05.2026 | M12: 5100001666 | N12: ZSCH | O12: Normal Sales | P12: 4110027035 | Q12: 03.09.2020 | R12: 5000 | S12: BAJAJ AUTO LIMITED (WALUJ) | V12: 27340676530V | W12: 1502020105 | X12: 52AU0123 BODY ASSLY 4S PETROL | Y12: =VLOOKUP(W12,Sheet4!$A$5:$B$71,2,0) -> RE STYLING | Z12: 87082900 | AA12: 15 | AB12: EA | AC12: 6570.77 | AD12: INR | AE12: 98561.55 | AF12: 0 | AG12: 98561.55 | AH12: 0 | AI12: 0 | AJ12: 0 | AK12: 0 | AL12: 98561.55 | AM12: 0 | AN12: 0 | AO12: 0 | AP12: 0 | AQ12: 0 | AR12: 0 | AS12: 0 | AT12: 0 | AU12: 98561.55 | AV12: 0 | AW12: 0 | AX12: 311000 | AY12: SALE FINISHED GOODS | AZ12: 49.75 | BA12: 49.75 | BB12: 0 | BC12: 52AU0123 | BD12: 1509 | BE12: FG Body | BF12: 5094107035 | BG12: 05.05.2026
A13: 1115 | B13: 1115 | C13: 10 | D13: 2 | E13: Three Wheelers | F13: F2 | G13: COMMERCIAL INVOICE | H13: 1526005951 | I13: 1000006213 | L13: 04.05.2026 | M13: 5100001666 | N13: ZSCH | O13: Normal Sales | P13: 4110027035 | Q13: 03.09.2020 | R13: 5000 | S13: BAJAJ AUTO LIMITED (WALUJ) | V13: 27340676530V | W13: 1502020105 | X13: 52AU0123 BODY ASSLY 4S PETROL | Y13: =VLOOKUP(W13,Sheet4!$A$5:$B$71,2,0) -> RE STYLING | Z13: 87082900 | AA13: 15 | AB13: EA | AC13: 6570.77 | AD13: INR | AE13: 98561.55 | AF13: 0 | AG13: 98561.55 | AH13: 0 | AI13: 0 | AJ13: 0 | AK13: 0 | AL13: 98561.55 | AM13: 0 | AN13: 0 | AO13: 0 | AP13: 0 | AQ13: 0 | AR13: 0 | AS13: 0 | AT13: 0 | AU13: 98561.55 | AV13: 0 | AW13: 0 | AX13: 311000 | AY13: SALE FINISHED GOODS | AZ13: 49.75 | BA13: 49.75 | BB13: 0 | BC13: 52AU0123 | BD13: 1509 | BE13: FG Body | BF13: 5094107203 | BG13: 05.05.2026
... A87: 1115 | B87: 1115 | C87: 10 | D87: 2 | E87: Three Wheelers | F87: F2 | G87: COMMERCIAL INVOICE | H87: 1526005856 | I87: 1000006122 | L87: 04.05.2026 | M87: 5100001100 | N87: ZSCH | O87: Normal Sales | P87: 4110004652 | Q87: 01.07.2017 | R87: 5000 | S87: BAJAJ AUTO LIMITED (WALUJ) | V87: 27340676530V | W87: 1502040164 | X87: 52BB0125 REAR COVER ASSLY GREEN LH | Y87: =VLOOKUP(W87,Sheet4!$A$5:$B$71,2,0) -> REAR COVER | Z87: 87082900 | AA87: 55 | AB87: EA | AC87: 160.52 | AD87: INR | AE87: 8828.6 | AF87: 0 | AG87: 8828.6 | AH87: 0 | AI87: 0 | AJ87: 0 | AK87: 0 | AL87: 8828.6 | AM87: 0 | AN87: 0 | AO87: 0 | AP87: 0 | AQ87: 0 | AR87: 0 | AS87: 0 | AT87: 0 | AU87: 8828.6 | AV87: 0 | AW87: 0 | AX87: 311000 | AY87: SALE FINISHED GOODS | AZ87: 1.166 | BA87: 1.166 | BB87: 0 | BC87: 52BB0125 | BD87: 1511 | BE87: FG Loose 3WH | BF87: 5094094589 | BG87: 04.05.2026
A88: 1115 | B88: 1115 | C88: 10 | D88: 2 | E88: Three Wheelers | F88: F2 | G88: COMMERCIAL INVOICE | H88: 1526005855 | I88: 1000006121 | L88: 04.05.2026 | M88: 5100001100 | N88: ZSCH | O88: Normal Sales | P88: 4110004652 | Q88: 01.07.2017 | R88: 5000 | S88: BAJAJ AUTO LIMITED (WALUJ) | V88: 27340676530V | W88: 1502040164 | X88: 52BB0125 REAR COVER ASSLY GREEN LH | Y88: =VLOOKUP(W88,Sheet4!$A$5:$B$71,2,0) -> REAR COVER | Z88: 87082900 | AA88: 80 | AB88: EA | AC88: 160.52 | AD88: INR | AE88: 12841.6 | AF88: 0 | AG88: 12841.6 | AH88: 0 | AI88: 0 | AJ88: 0 | AK88: 0 | AL88: 12841.6 | AM88: 0 | AN88: 0 | AO88: 0 | AP88: 0 | AQ88: 0 | AR88: 0 | AS88: 0 | AT88: 0 | AU88: 12841.6 | AV88: 0 | AW88: 0 | AX88: 311000 | AY88: SALE FINISHED GOODS | AZ88: 1.166 | BA88: 1.166 | BB88: 0 | BC88: 52BB0125 | BD88: 1511 | BE88: FG Loose 3WH | BF88: PENDING | BG88: Pending
A89: 1115 | B89: 1115 | C89: 10 | D89: 2 | E89: Three Wheelers | F89: F2 | G89: COMMERCIAL INVOICE | H89: 1526005854 | I89: 1000006118 | L89: 04.05.2026 | M89: 5100001636 | N89: ZSCH | O89: Normal Sales | P89: 4110026445 | Q89: 23.07.2020 | R89: 5000 | S89: BAJAJ AUTO LIMITED (WALUJ) | V89: 27340676530V | W89: 1502020101 | X89: 52BA0852 ASSLY BODY COMPACT DIESEL | Y89: =VLOOKUP(W89,Sheet4!$A$5:$B$71,2,0) -> RE STYLING | Z89: 87082900 | AA89: 15 | AB89: EA | AC89: 6240.88 | AD89: INR | AE89: 93613.2 | AF89: 0 | AG89: 93613.2 | AH89: 0 | AI89: 0 | AJ89: 0 | AK89: 0 | AL89: 93613.2 | AM89: 0 | AN89: 0 | AO89: 0 | AP89: 0 | AQ89: 0 | AR89: 0 | AS89: 0 | AT89: 0 | AU89: 93613.2 | AV89: 0 | AW89: 0 | AX89: 311000 | AY89: SALE FINISHED GOODS | AZ89: 58 | BA89: 58 | BB89: 0 | BC89: 52BA0852 | BD89: 1509 | BE89: FG Body | BF89: 5094107388 | BG89: 05.05.2026
A90: 1115 | B90: 1115 | C90: 10 | D90: 2 | E90: Three Wheelers | F90: F2 | G90: COMMERCIAL INVOICE | H90: 1526005853 | I90: 1000006117 | L90: 04.05.2026 | M90: 5100001636 | N90: ZSCH | O90: Normal Sales | P90: 4110026445 | Q90: 23.07.2020 | R90: 5000 | S90: BAJAJ AUTO LIMITED (WALUJ) | V90: 27340676530V | W90: 1502020101 | X90: 52BA0852 ASSLY BODY COMPACT DIESEL | Y90: =VLOOKUP(W90,Sheet4!$A$5:$B$71,2,0) -> RE STYLING | Z90: 87082900 | AA90: 15 | AB90: EA | AC90: 6240.88 | AD90: INR | AE90: 93613.2 | AF90: 0 | AG90: 93613.2 | AH90: 0 | AI90: 0 | AJ90: 0 | AK90: 0 | AL90: 93613.2 | AM90: 0 | AN90: 0 | AO90: 0 | AP90: 0 | AQ90: 0 | AR90: 0 | AS90: 0 | AT90: 0 | AU90: 93613.2 | AV90: 0 | AW90: 0 | AX90: 311000 | AY90: SALE FINISHED GOODS | AZ90: 58 | BA90: 58 | BB90: 0 | BC90: 52BA0852 | BD90: 1509 | BE90: FG Body | BF90: 5094107316 | BG90: 05.05.2026
A91: 1115 | B91: 1115 | C91: 10 | D91: 2 | E91: Three Wheelers | F91: F2 | G91: COMMERCIAL INVOICE | H91: 1526005852 | I91: 1000006116 | L91: 04.05.2026 | M91: 5100001666 | N91: ZSCH | O91: Normal Sales | P91: 4110027035 | Q91: 03.09.2020 | R91: 5000 | S91: BAJAJ AUTO LIMITED (WALUJ) | V91: 27340676530V | W91: 1502020105 | X91: 52AU0123 BODY ASSLY 4S PETROL | Y91: =VLOOKUP(W91,Sheet4!$A$5:$B$71,2,0) -> RE STYLING | Z91: 87082900 | AA91: 15 | AB91: EA | AC91: 6570.77 | AD91: INR | AE91: 98561.55 | AF91: 0 | AG91: 98561.55 | AH91: 0 | AI91: 0 | AJ91: 0 | AK91: 0 | AL91: 98561.55 | AM91: 0 | AN91: 0 | AO91: 0 | AP91: 0 | AQ91: 0 | AR91: 0 | AS91: 0 | AT91: 0 | AU91: 98561.55 | AV91: 0 | AW91: 0 | AX91: 311000 | AY91: SALE FINISHED GOODS | AZ91: 49.75 | BA91: 49.75 | BB91: 0 | BC91: 52AU0123 | BD91: 1509 | BE91: FG Body | BF91: 5094098565 | BG91: 04.05.2026
A92: 1115 | B92: 1115 | C92: 10 | D92: 2 | E92: Three Wheelers | F92: F2 | G92: COMMERCIAL INVOICE | H92: 1526005851 | I92: 1000006115 | L92: 04.05.2026 | M92: 5100001899 | N92: ZSCH | O92: Normal Sales | P92: 4110041854 | Q92: 03.03.2023 | R92: 5000 | S92: BAJAJ AUTO LIMITED (WALUJ) | V92: 27340676530V | W92: 1502040267 | X92: AZ111331_06 SUPPORT ASSLY DASHBOARD | Y92: =VLOOKUP(W92,Sheet4!$A$5:$B$71,2,0) -> DASH BOARD | Z92: 87082900 | AA92: 416 | AB92: EA | AC92: 290.9 | AD92: INR | AE92: 121014.4 | AF92: 0 | AG92: 121014.4 | AH92: 0 | AI92: 0 | AJ92: 0 | AK92: 0 | AL92: 121014.4 | AM92: 0 | AN92: 0 | AO92: 0 | AP92: 0 | AQ92: 0 | AR92: 0 | AS92: 0 | AT92: 0 | AU92: 121014.4 | AV92: 0 | AW92: 0 | AX92: 311000 | AY92: SALE FINISHED GOODS | AZ92: 4.5 | BA92: 4.5 | BB92: 0 | BC92: AZ111331 | BD92: 1511 | BE92: FG Loose 3WH | BF92: 5094127541 | BG92: 05.05.2026
A93: 1115 | B93: 1115 | C93: 10 | D93: 2 | E93: Three Wheelers | F93: F2 | G93: COMMERCIAL INVOICE | H93: 1526005850 | I93: 1000006111 | L93: 04.05.2026 | M93: 5100001666 | N93: ZSCH | O93: Normal Sales | P93: 4110027035 | Q93: 03.09.2020 | R93: 5000 | S93: BAJAJ AUTO LIMITED (WALUJ) | V93: 27340676530V | W93: 1502020105 | X93: 52AU0123 BODY ASSLY 4S PETROL | Y93: =VLOOKUP(W93,Sheet4!$A$5:$B$71,2,0) -> RE STYLING | Z93: 87082900 | AA93: 15 | AB93: EA | AC93: 6570.77 | AD93: INR | AE93: 98561.55 | AF93: 0 | AG93: 98561.55 | AH93: 0 | AI93: 0 | AJ93: 0 | AK93: 0 | AL93: 98561.55 | AM93: 0 | AN93: 0 | AO93: 0 | AP93: 0 | AQ93: 0 | AR93: 0 | AS93: 0 | AT93: 0 | AU93: 98561.55 | AV93: 0 | AW93: 0 | AX93: 311000 | AY93: SALE FINISHED GOODS | AZ93: 49.75 | BA93: 49.75 | BB93: 0 | BC93: 52AU0123 | BD93: 1509 | BE93: FG Body | BF93: 5094098393 | BG93: 04.05.2026
A94: 1115 | B94: 1115 | C94: 10 | D94: 2 | E94: Three Wheelers | F94: F2 | G94: COMMERCIAL INVOICE | H94: 1526005849 | I94: 1000006110 | L94: 04.05.2026 | M94: 5100001928 | N94: ZSCH | O94: Normal Sales | P94: 4110057393 | Q94: 28.11.2024 | R94: 5000 | S94: BAJAJ AUTO LIMITED (WALUJ) | V94: 27340676530V | W94: 1502020122 | X94: 52AH0692 BODY ASSLY MAXIMA Z EV | Y94: =VLOOKUP(W94,Sheet4!$A$5:$B$71,2,0) -> MAX UG NEW EV | Z94: 87082900 | AA94: 10 | AB94: EA | AC94: 9566.51 | AD94: INR | AE94: 95665.1 | AF94: 0 | AG94: 95665.1 | AH94: 0 | AI94: 0 | AJ94: 0 | AK94: 0 | AL94: 95665.1 | AM94: 0 | AN94: 0 | AO94: 0 | AP94: 0 | AQ94: 0 | AR94: 0 | AS94: 0 | AT94: 0 | AU94: 95665.1 | AV94: 0 | AW94: 0 | AX94: 311000 | AY94: SALE FINISHED GOODS | AZ94: 0 | BA94: 61 | BB94: -61 | BC94: 52AH0692 | BD94: 1509 | BE94: FG Body | BF94: 5094094564 | BG94: 04.05.2026
A95: 1115 | B95: 1115 | C95: 10 | D95: 2 | E95: Three Wheelers | F95: F2 | G95: COMMERCIAL INVOICE | H95: 1526005848 | I95: 1000006109 | L95: 04.05.2026 | M95: 5100001928 | N95: ZSCH | O95: Normal Sales | P95: 4110057393 | Q95: 28.11.2024 | R95: 5000 | S95: BAJAJ AUTO LIMITED (WALUJ) | V95: 27340676530V | W95: 1502020122 | X95: 52AH0692 BODY ASSLY MAXIMA Z EV | Y95: =VLOOKUP(W95,Sheet4!$A$5:$B$71,2,0) -> MAX UG NEW EV | Z95: 87082900 | AA95: 10 | AB95: EA | AC95: 9566.51 | AD95: INR | AE95: 95665.1 | AF95: 0 | AG95: 95665.1 | AH95: 0 | AI95: 0 | AJ95: 0 | AK95: 0 | AL95: 95665.1 | AM95: 0 | AN95: 0 | AO95: 0 | AP95: 0 | AQ95: 0 | AR95: 0 | AS95: 0 | AT95: 0 | AU95: 95665.1 | AV95: 0 | AW95: 0 | AX95: 311000 | AY95: SALE FINISHED GOODS | AZ95: 0 | BA95: 61 | BB95: -61 | BC95: 52AH0692 | BD95: 1509 | BE95: FG Body | BF95: 5094096326 | BG95: 04.05.2026
A96: 1115 | B96: 1115 | C96: 10 | D96: 2 | E96: Three Wheelers | F96: F2 | G96: COMMERCIAL INVOICE | H96: 1526005846 | I96: 1000006107 | L96: 04.05.2026 | M96: 5100001666 | N96: ZSCH | O96: Normal Sales | P96: 4110027035 | Q96: 03.09.2020 | R96: 5000 | S96: BAJAJ AUTO LIMITED (WALUJ) | V96: 27340676530V | W96: 1502020105 | X96: 52AU0123 BODY ASSLY 4S PETROL | Y96: =VLOOKUP(W96,Sheet4!$A$5:$B$71,2,0) -> RE STYLING | Z96: 87082900 | AA96: 15 | AB96: EA | AC96: 6570.77 | AD96: INR | AE96: 98561.55 | AF96: 0 | AG96: 98561.55 | AH96: 0 | AI96: 0 | AJ96: 0 | AK96: 0 | AL96: 98561.55 | AM96: 0 | AN96: 0 | AO96: 0 | AP96: 0 | AQ96: 0 | AR96: 0 | AS96: 0 | AT96: 0 | AU96: 98561.55 | AV96: 0 | AW96: 0 | AX96: 311000 | AY96: SALE FINISHED GOODS | AZ96: 49.75 | BA96: 49.75 | BB96: 0 | BC96: 52AU0123 | BD96: 1509 | BE96: FG Body | BF96: 5094098122 | BG96: 04.05.2026
A97: 1115 | B97: 1115 | C97: 10 | D97: 2 | E97: Three Wheelers | F97: F2 | G97: COMMERCIAL INVOICE | H97: 1526005845 | I97: 1000006106 | L97: 04.05.2026 | M97: 5100001666 | N97: ZSCH | O97: Normal Sales | P97: 4110027035 | Q97: 03.09.2020 | R97: 5000 | S97: BAJAJ AUTO LIMITED (WALUJ) | V97: 27340676530V | W97: 1502020105 | X97: 52AU0123 BODY ASSLY 4S PETROL | Y97: =VLOOKUP(W97,Sheet4!$A$5:$B$71,2,0) -> RE STYLING | Z97: 87082900 | AA97: 15 | AB97: EA | AC97: 6570.77 | AD97: INR | AE97: 98561.55 | AF97: 0 | AG97: 98561.55 | AH97: 0 | AI97: 0 | AJ97: 0 | AK97: 0 | AL97: 98561.55 | AM97: 0 | AN97: 0 | AO97: 0 | AP97: 0 | AQ97: 0 | AR97: 0 | AS97: 0 | AT97: 0 | AU97: 98561.55 | AV97: 0 | AW97: 0 | AX97: 311000 | AY97: SALE FINISHED GOODS | AZ97: 49.75 | BA97: 49.75 | BB97: 0 | BC97: 52AU0123 | BD97: 1509 | BE97: FG Body | BF97: 5094097830 | BG97: 04.05.2026
A98: 1115 | B98: 1115 | C98: 10 | D98: 2 | E98: Three Wheelers | F98: F2 | G98: COMMERCIAL INVOICE | H98: 1526005844 | I98: 1000006105 | L98: 04.05.2026 | M98: 5100001666 | N98: ZSCH | O98: Normal Sales | P98: 4110027035 | Q98: 03.09.2020 | R98: 5000 | S98: BAJAJ AUTO LIMITED (WALUJ) | V98: 27340676530V | W98: 1502020105 | X98: 52AU0123 BODY ASSLY 4S PETROL | Y98: =VLOOKUP(W98,Sheet4!$A$5:$B$71,2,0) -> RE STYLING | Z98: 87082900 | AA98: 15 | AB98: EA | AC98: 6570.77 | AD98: INR | AE98: 98561.55 | AF98: 0 | AG98: 98561.55 | AH98: 0 | AI98: 0 | AJ98: 0 | AK98: 0 | AL98: 98561.55 | AM98: 0 | AN98: 0 | AO98: 0 | AP98: 0 | AQ98: 0 | AR98: 0 | AS98: 0 | AT98: 0 | AU98: 98561.55 | AV98: 0 | AW98: 0 | AX98: 311000 | AY98: SALE FINISHED GOODS | AZ98: 49.75 | BA98: 49.75 | BB98: 0 | BC98: 52AU0123 | BD98: 1509 | BE98: FG Body | BF98: 5094097995 | BG98: 04.05.2026
A99: 1115 | B99: 1115 | C99: 10 | D99: 2 | E99: Three Wheelers | F99: F2 | G99: COMMERCIAL INVOICE | H99: 1526005843 | I99: 1000006098 | L99: 04.05.2026 | M99: 5100001928 | N99: ZSCH | O99: Normal Sales | P99: 4110057393 | Q99: 28.11.2024 | R99: 5000 | S99: BAJAJ AUTO LIMITED (WALUJ) | V99: 27340676530V | W99: 1502020122 | X99: 52AH0692 BODY ASSLY MAXIMA Z EV | Y99: =VLOOKUP(W99,Sheet4!$A$5:$B$71,2,0) -> MAX UG NEW EV | Z99: 87082900 | AA99: 10 | AB99: EA | AC99: 9566.51 | AD99: INR | AE99: 95665.1 | AF99: 0 | AG99: 95665.1 | AH99: 0 | AI99: 0 | AJ99: 0 | AK99: 0 | AL99: 95665.1 | AM99: 0 | AN99: 0 | AO99: 0 | AP99: 0 | AQ99: 0 | AR99: 0 | AS99: 0 | AT99: 0 | AU99: 95665.1 | AV99: 0 | AW99: 0 | AX99: 311000 | AY99: SALE FINISHED GOODS | AZ99: 0 | BA99: 61 | BB99: -61 | BC99: 52AH0692 | BD99: 1509 | BE99: FG Body | BF99: 5094092904 | BG99: 04.05.2026
A100: 1115 | B100: 1115 | C100: 10 | D100: 2 | E100: Three Wheelers | F100: F2 | G100: COMMERCIAL INVOICE | H100: 1526005842 | I100: 1000006097 | L100: 04.05.2026 | M100: 5100001603 | N100: ZSCH | O100: Normal Sales | P100: 4110025468 | Q100: 19.03.2020 | R100: 5000 | S100: BAJAJ AUTO LIMITED (WALUJ) | V100: 27340676530V | W100: 1502020102 | X100: 52BB0638 BODY ASSLY MAXIMA X WIDE | Y100: =VLOOKUP(W100,Sheet4!$A$5:$B$71,2,0) -> MAXIMA HD | Z100: 87082900 | AA100: 8 | AB100: EA | AC100: 8593.51 | AD100: INR | AE100: 68748.08 | AF100: 0 | AG100: 68748.08 | AH100: 0 | AI100: 0 | AJ100: 0 | AK100: 0 | AL100: 68748.08 | AM100: 0 | AN100: 0 | AO100: 0 | AP100: 0 | AQ100: 0 | AR100: 0 | AS100: 0 | AT100: 0 | AU100: 68748.08 | AV100: 0 | AW100: 0 | AX100: 311000 | AY100: SALE FINISHED GOODS | AZ100: 93.34 | BA100: 75.43 | BB100: 17.91 | BC100: 52BB0638 | BD100: 1509 | BE100: FG Body | BF100: 5094101747 | BG100: 04.05.2026
... A118: 1115 | B118: 1115 | C118: 10 | D118: 2 | E118: Three Wheelers | F118: F2 | G118: COMMERCIAL INVOICE | H118: 1526005820 | I118: 1000006076 | L118: 04.05.2026 | M118: 5100001928 | N118: ZSCH | O118: Normal Sales | P118: 4110057393 | Q118: 28.11.2024 | R118: 5000 | S118: BAJAJ AUTO LIMITED (WALUJ) | V118: 27340676530V | W118: 1502020122 | X118: 52AH0692 BODY ASSLY MAXIMA Z EV | Y118: =VLOOKUP(W118,Sheet4!$A$5:$B$71,2,0) -> MAX UG NEW EV | Z118: 87082900 | AA118: 10 | AB118: EA | AC118: 9566.51 | AD118: INR | AE118: 95665.1 | AF118: 0 | AG118: 95665.1 | AH118: 0 | AI118: 0 | AJ118: 0 | AK118: 0 | AL118: 95665.1 | AM118: 0 | AN118: 0 | AO118: 0 | AP118: 0 | AQ118: 0 | AR118: 0 | AS118: 0 | AT118: 0 | AU118: 95665.1 | AV118: 0 | AW118: 0 | AX118: 311000 | AY118: SALE FINISHED GOODS | AZ118: 0 | BA118: 61 | BB118: -61 | BC118: 52AH0692 | BD118: 1509 | BE118: FG Body | BF118: 5094090904 | BG118: 04.05.2026
A119: 1115 | B119: 1115 | C119: 10 | D119: 2 | E119: Three Wheelers | F119: F2 | G119: COMMERCIAL INVOICE | H119: 1526005818 | I119: 1000006075 | L119: 04.05.2026 | M119: 5100001899 | N119: ZSCH | O119: Normal Sales | P119: 4110041854 | Q119: 03.03.2023 | R119: 5000 | S119: BAJAJ AUTO LIMITED (WALUJ) | V119: 27340676530V | W119: 1502040267 | X119: AZ111331_06 SUPPORT ASSLY DASHBOARD | Y119: =VLOOKUP(W119,Sheet4!$A$5:$B$71,2,0) -> DASH BOARD | Z119: 87082900 | AA119: 416 | AB119: EA | AC119: 290.9 | AD119: INR | AE119: 121014.4 | AF119: 0 | AG119: 121014.4 | AH119: 0 | AI119: 0 | AJ119: 0 | AK119: 0 | AL119: 121014.4 | AM119: 0 | AN119: 0 | AO119: 0 | AP119: 0 | AQ119: 0 | AR119: 0 | AS119: 0 | AT119: 0 | AU119: 121014.4 | AV119: 0 | AW119: 0 | AX119: 311000 | AY119: SALE FINISHED GOODS | AZ119: 4.5 | BA119: 4.5 | BB119: 0 | BC119: AZ111331 | BD119: 1511 | BE119: FG Loose 3WH | BF119: PENDING | BG119: Pending
A120: 1115 | B120: 1115 | C120: 10 | D120: 2 | E120: Three Wheelers | F120: F2 | G120: COMMERCIAL INVOICE | H120: 1526005817 | I120: 1000006074 | L120: 04.05.2026 | M120: 5100001899 | N120: ZSCH | O120: Normal Sales | P120: 4110041854 | Q120: 03.03.2023 | R120: 5000 | S120: BAJAJ AUTO LIMITED (WALUJ) | V120: 27340676530V | W120: 1502040267 | X120: AZ111331_06 SUPPORT ASSLY DASHBOARD | Y120: =VLOOKUP(W120,Sheet4!$A$5:$B$71,2,0) -> DASH BOARD | Z120: 87082900 | AA120: 416 | AB120: EA | AC120: 290.9 | AD120: INR | AE120: 121014.4 | AF120: 0 | AG120: 121014.4 | AH120: 0 | AI120: 0 | AJ120: 0 | AK120: 0 | AL120: 121014.4 | AM120: 0 | AN120: 0 | AO120: 0 | AP120: 0 | AQ120: 0 | AR120: 0 | AS120: 0 | AT120: 0 | AU120: 121014.4 | AV120: 0 | AW120: 0 | AX120: 311000 | AY120: SALE FINISHED GOODS | AZ120: 4.5 | BA120: 4.5 | BB120: 0 | BC120: AZ111331 | BD120: 1511 | BE120: FG Loose 3WH | BF120: 5094097397 | BG120: 04.05.2026
A121: 1115 | B121: 1115 | C121: 10 | D121: 2 | E121: Three Wheelers | F121: F2 | G121: COMMERCIAL INVOICE | H121: 1526005864 | I121: 1000006128 | L121: 04.05.2026 | M121: 5100001903 | N121: ZSCH | O121: Normal Sales | P121: 4110043907 | Q121: 03.07.2023 | R121: 5000 | S121: BAJAJ AUTO LIMITED (WALUJ) | V121: 27340676530V | W121: 1502040216 | X121: AA161289- ASSEMBLY MUDGUARD FRONT | Y121: =VLOOKUP(W121,Sheet4!$A$5:$B$71,2,0) -> FRONT MUDGAURD | Z121: 87082900 | AA121: 300 | AB121: EA | AC121: 174.11 | AD121: INR | AE121: 52233 | AF121: 0 | AG121: 52233 | AH121: 0 | AI121: 0 | AJ121: 0 | AK121: 0 | AL121: 52233 | AM121: 0 | AN121: 0 | AO121: 0 | AP121: 0 | AQ121: 0 | AR121: 0 | AS121: 0 | AT121: 0 | AU121: 52233 | AV121: 0 | AW121: 0 | AX121: 311000 | AY121: SALE FINISHED GOODS | AZ121: 2.573 | BA121: 1.491 | BB121: 1.082 | BC121: AA161289 | BD121: 1511 | BE121: FG Loose 3WH | BF121: 5094101162 | BG121: 04.05.2026
A122: 1115 | B122: 1115 | C122: 10 | D122: 2 | E122: Three Wheelers | F122: F2 | G122: COMMERCIAL INVOICE | H122: 1526005911 | I122: 1000006174 | L122: 04.05.2026 | M122: 5100001636 | N122: ZSCH | O122: Normal Sales | P122: 4110026445 | Q122: 23.07.2020 | R122: 5000 | S122: BAJAJ AUTO LIMITED (WALUJ) | V122: 27340676530V | W122: 1502020101 | X122: 52BA0852 ASSLY BODY COMPACT DIESEL | Y122: =VLOOKUP(W122,Sheet4!$A$5:$B$71,2,0) -> RE STYLING | Z122: 87082900 | AA122: 15 | AB122: EA | AC122: 6240.88 | AD122: INR | AE122: 93613.2 | AF122: 0 | AG122: 93613.2 | AH122: 0 | AI122: 0 | AJ122: 0 | AK122: 0 | AL122: 93613.2 | AM122: 0 | AN122: 0 | AO122: 0 | AP122: 0 | AQ122: 0 | AR122: 0 | AS122: 0 | AT122: 0 | AU122: 93613.2 | AV122: 0 | AW122: 0 | AX122: 311000 | AY122: SALE FINISHED GOODS | AZ122: 58 | BA122: 58 | BB122: 0 | BC122: 52BA0852 | BD122: 1509 | BE122: FG Body | BF122: 5094107312 | BG122: 05.05.2026
A123: 1115 | B123: 1115 | C123: 10 | D123: 2 | E123: Three Wheelers | F123: F2 | G123: COMMERCIAL INVOICE | H123: 1526005910 | I123: 1000006173 | L123: 04.05.2026 | M123: 5100001928 | N123: ZSCH | O123: Normal Sales | P123: 4110057393 | Q123: 28.11.2024 | R123: 5000 | S123: BAJAJ AUTO LIMITED (WALUJ) | V123: 27340676530V | W123: 1502020122 | X123: 52AH0692 BODY ASSLY MAXIMA Z EV | Y123: =VLOOKUP(W123,Sheet4!$A$5:$B$71,2,0) -> MAX UG NEW EV | Z123: 87082900 | AA123: 10 | AB123: EA | AC123: 9566.51 | AD123: INR | AE123: 95665.1 | AF123: 0 | AG123: 95665.1 | AH123: 0 | AI123: 0 | AJ123: 0 | AK123: 0 | AL123: 95665.1 | AM123: 0 | AN123: 0 | AO123: 0 | AP123: 0 | AQ123: 0 | AR123: 0 | AS123: 0 | AT123: 0 | AU123: 95665.1 | AV123: 0 | AW123: 0 | AX123: 311000 | AY123: SALE FINISHED GOODS | AZ123: 0 | BA123: 61 | BB123: -61 | BC123: 52AH0692 | BD123: 1509 | BE123: FG Body | BF123: 5094104403 | BG123: 04.05.2026
